Workbook

Sheet Information
B1: Client:
B2: Mine:
B3: Block ID:
B4: Planned Hole Diameter (mm): | C4: 165
B5: Final Stemming (m): | C5: 1
B6: Average In-Hole Density (g/cc): | C6: 1.2
B7: Rig Operator:
B8: Date of Calipering:

Sheet Table
A1: BME Borehole Tracking Summary Table
A2: Hole Name | B2: Depth (m) | C2: Mean Diam | D2: Min Diam | E2: Max Diam | F2: Planned Diam | G2: Overbreak % | H2: Min Dev | I2: Mean Dev | J2: Max Dev | K2: Stemming (m) | L2: Exp Depth (m) | M2: Density | N2: Exp Mass (kg) | O2: Theo Mass (kg)
A3: BH_001 | B3: ==IF(ISREF(Sheet1!A2),MAX(Sheet1!A:A),"") | C3: ==IF(ISREF(Sheet1!B2),AVERAGE(Sheet1!B:B),"") | D3: ==IF(ISREF(Sheet1!B2),MIN(Sheet1!B:B),"") | E3: ==IF(ISREF(Sheet1!B2),MAX(Sheet1!B:B),"") | F3: ==Information!C | G3: ==IF(C3>0,((C3-F3)/F3)*100,"") | H3: ==IF(D3>0,D3-F3,"") | I3: ==IF(C3>0,C3-F3,"") | J3: ==IF(E3>0,E3-F3,"") | K3: ==Information!C | L3: ==IF(B3>K3,B3-K3,0) | M3: ==Information!C | N3: ==IF(L3>0,PI()*((C3/2000)^2)*L3*M3*1000,"") | O3: ==IF(L3>0,PI()*((F3/2000)^2)*L3*M3*1000,"")
A4: BH_002 | B4: ==IF(ISREF(Sheet2!A2),MAX(Sheet2!A:A),"") | C4: ==IF(ISREF(Sheet2!B2),AVERAGE(Sheet2!B:B),"") | D4: ==IF(ISREF(Sheet2!B2),MIN(Sheet2!B:B),"") | E4: ==IF(ISREF(Sheet2!B2),MAX(Sheet2!B:B),"") | F4: ==Information!C | G4: ==IF(C4>0,((C4-F4)/F4)*100,"") | H4: ==IF(D4>0,D4-F4,"") | I4: ==IF(C4>0,C4-F4,"") | J4: ==IF(E4>0,E4-F4,"") | K4: ==Information!C | L4: ==IF(B4>K4,B4-K4,0) | M4: ==Information!C | N4: ==IF(L4>0,PI()*((C4/2000)^2)*L4*M4*1000,"") | O4: ==IF(L4>0,PI()*((F4/2000)^2)*L4*M4*1000,"")
A5: BH_003 | B5: ==IF(ISREF(Sheet3!A2),MAX(Sheet3!A:A),"") | C5: ==IF(ISREF(Sheet3!B2),AVERAGE(Sheet3!B:B),"") | D5: ==IF(ISREF(Sheet3!B2),MIN(Sheet3!B:B),"") | E5: ==IF(ISREF(Sheet3!B2),MAX(Sheet3!B:B),"") | F5: ==Information!C | G5: ==IF(C5>0,((C5-F5)/F5)*100,"") | H5: ==IF(D5>0,D5-F5,"") | I5: ==IF(C5>0,C5-F5,"") | J5: ==IF(E5>0,E5-F5,"") | K5: ==Information!C | L5: ==IF(B5>K5,B5-K5,0) | M5: ==Information!C | N5: ==IF(L5>0,PI()*((C5/2000)^2)*L5*M5*1000,"") | O5: ==IF(L5>0,PI()*((F5/2000)^2)*L5*M5*1000,"")
A6: BH_004 | B6: ==IF(ISREF(Sheet4!A2),MAX(Sheet4!A:A),"") | C6: ==IF(ISREF(Sheet4!B2),AVERAGE(Sheet4!B:B),"") | D6: ==IF(ISREF(Sheet4!B2),MIN(Sheet4!B:B),"") | E6: ==IF(ISREF(Sheet4!B2),MAX(Sheet4!B:B),"") | F6: ==Information!C | G6: ==IF(C6>0,((C6-F6)/F6)*100,"") | H6: ==IF(D6>0,D6-F6,"") | I6: ==IF(C6>0,C6-F6,"") | J6: ==IF(E6>0,E6-F6,"") | K6: ==Information!C | L6: ==IF(B6>K6,B6-K6,0) | M6: ==Information!C | N6: ==IF(L6>0,PI()*((C6/2000)^2)*L6*M6*1000,"") | O6: ==IF(L6>0,PI()*((F6/2000)^2)*L6*M6*1000,"")
A7: BH_005 | B7: ==IF(ISREF(Sheet5!A2),MAX(Sheet5!A:A),"") | C7: ==IF(ISREF(Sheet5!B2),AVERAGE(Sheet5!B:B),"") | D7: ==IF(ISREF(Sheet5!B2),MIN(Sheet5!B:B),"") | E7: ==IF(ISREF(Sheet5!B2),MAX(Sheet5!B:B),"") | F7: ==Information!C | G7: ==IF(C7>0,((C7-F7)/F7)*100,"") | H7: ==IF(D7>0,D7-F7,"") | I7: ==IF(C7>0,C7-F7,"") | J7: ==IF(E7>0,E7-F7,"") | K7: ==Information!C | L7: ==IF(B7>K7,B7-K7,0) | M7: ==Information!C | N7: ==IF(L7>0,PI()*((C7/2000)^2)*L7*M7*1000,"") | O7: ==IF(L7>0,PI()*((F7/2000)^2)*L7*M7*1000,"")
A8: BH_006 | B8: ==IF(ISREF(Sheet6!A2),MAX(Sheet6!A:A),"") | C8: ==IF(ISREF(Sheet6!B2),AVERAGE(Sheet6!B:B),"") | D8: ==IF(ISREF(Sheet6!B2),MIN(Sheet6!B:B),"") | E8: ==IF(ISREF(Sheet6!B2),MAX(Sheet6!B:B),"") | F8: ==Information!C | G8: ==IF(C8>0,((C8-F8)/F8)*100,"") | H8: ==IF(D8>0,D8-F8,"") | I8: ==IF(C8>0,C8-F8,"") | J8: ==IF(E8>0,E8-F8,"") | K8: ==Information!C | L8: ==IF(B8>K8,B8-K8,0) | M8: ==Information!C | N8: ==IF(L8>0,PI()*((C8/2000)^2)*L8*M8*1000,"") | O8: ==IF(L8>0,PI()*((F8/2000)^2)*L8*M8*1000,"")
A9: BH_007 | B9: ==IF(ISREF(Sheet7!A2),MAX(Sheet7!A:A),"") | C9: ==IF(ISREF(Sheet7!B2),AVERAGE(Sheet7!B:B),"") | D9: ==IF(ISREF(Sheet7!B2),MIN(Sheet7!B:B),"") | E9: ==IF(ISREF(Sheet7!B2),MAX(Sheet7!B:B),"") | F9: ==Information!C | G9: ==IF(C9>0,((C9-F9)/F9)*100,"") | H9: ==IF(D9>0,D9-F9,"") | I9: ==IF(C9>0,C9-F9,"") | J9: ==IF(E9>0,E9-F9,"") | K9: ==Information!C | L9: ==IF(B9>K9,B9-K9,0) | M9: ==Information!C | N9: ==IF(L9>0,PI()*((C9/2000)^2)*L9*M9*1000,"") | O9: ==IF(L9>0,PI()*((F9/2000)^2)*L9*M9*1000,"")
A10: BH_008 | B10: ==IF(ISREF(Sheet8!A2),MAX(Sheet8!A:A),"") | C10: ==IF(ISREF(Sheet8!B2),AVERAGE(Sheet8!B:B),"") | D10: ==IF(ISREF(Sheet8!B2),MIN(Sheet8!B:B),"") | E10: ==IF(ISREF(Sheet8!B2),MAX(Sheet8!B:B),"") | F10: ==Information!C | G10: ==IF(C10>0,((C10-F10)/F10)*100,"") | H10: ==IF(D10>0,D10-F10,"") | I10: ==IF(C10>0,C10-F10,"") | J10: ==IF(E10>0,E10-F10,"") | K10: ==Information!C | L10: ==IF(B10>K10,B10-K10,0) | M10: ==Information!C | N10: ==IF(L10>0,PI()*((C10/2000)^2)*L10*M10*1000,"") | O10: ==IF(L10>0,PI()*((F10/2000)^2)*L10*M10*1000,"")
A11: BH_009 | B11: ==IF(ISREF(Sheet9!A2),MAX(Sheet9!A:A),"") | C11: ==IF(ISREF(Sheet9!B2),AVERAGE(Sheet9!B:B),"") | D11: ==IF(ISREF(Sheet9!B2),MIN(Sheet9!B:B),"") | E11: ==IF(ISREF(Sheet9!B2),MAX(Sheet9!B:B),"") | F11: ==Information!C | G11: ==IF(C11>0,((C11-F11)/F11)*100,"") | H11: ==IF(D11>0,D11-F11,"") | I11: ==IF(C11>0,C11-F11,"") | J11: ==IF(E11>0,E11-F11,"") | K11: ==Information!C | L11: ==IF(B11>K11,B11-K11,0) | M11: ==Information!C | N11: ==IF(L11>0,PI()*((C11/2000)^2)*L11*M11*1000,"") | O11: ==IF(L11>0,PI()*((F11/2000)^2)*L11*M11*1000,"")
A12: BH_010 | B12: ==IF(ISREF(Sheet10!A2),MAX(Sheet10!A:A),"") | C12: ==IF(ISREF(Sheet10!B2),AVERAGE(Sheet10!B:B),"") | D12: ==IF(ISREF(Sheet10!B2),MIN(Sheet10!B:B),"") | E12: ==IF(ISREF(Sheet10!B2),MAX(Sheet10!B:B),"") | F12: ==Information!C | G12: ==IF(C12>0,((C12-F12)/F12)*100,"") | H12: ==IF(D12>0,D12-F12,"") | I12: ==IF(C12>0,C12-F12,"") | J12: ==IF(E12>0,E12-F12,"") | K12: ==Information!C | L12: ==IF(B12>K12,B12-K12,0) | M12: ==Information!C | N12: ==IF(L12>0,PI()*((C12/2000)^2)*L12*M12*1000,"") | O12: ==IF(L12>0,PI()*((F12/2000)^2)*L12*M12*1000,"")
A13: BH_011 | B13: ==IF(ISREF(Sheet11!A2),MAX(Sheet11!A:A),"") | C13: ==IF(ISREF(Sheet11!B2),AVERAGE(Sheet11!B:B),"") | D13: ==IF(ISREF(Sheet11!B2),MIN(Sheet11!B:B),"") | E13: ==IF(ISREF(Sheet11!B2),MAX(Sheet11!B:B),"") | F13: ==Information!C | G13: ==IF(C13>0,((C13-F13)/F13)*100,"") | H13: ==IF(D13>0,D13-F13,"") | I13: ==IF(C13>0,C13-F13,"") | J13: ==IF(E13>0,E13-F13,"") | K13: ==Information!C | L13: ==IF(B13>K13,B13-K13,0) | M13: ==Information!C | N13: ==IF(L13>0,PI()*((C13/2000)^2)*L13*M13*1000,"") | O13: ==IF(L13>0,PI()*((F13/2000)^2)*L13*M13*1000,"")
A14: BH_012 | B14: ==IF(ISREF(Sheet12!A2),MAX(Sheet12!A:A),"") | C14: ==IF(ISREF(Sheet12!B2),AVERAGE(Sheet12!B:B),"") | D14: ==IF(ISREF(Sheet12!B2),MIN(Sheet12!B:B),"") | E14: ==IF(ISREF(Sheet12!B2),MAX(Sheet12!B:B),"") | F14: ==Information!C | G14: ==IF(C14>0,((C14-F14)/F14)*100,"") | H14: ==IF(D14>0,D14-F14,"") | I14: ==IF(C14>0,C14-F14,"") | J14: ==IF(E14>0,E14-F14,"") | K14: ==Information!C | L14: ==IF(B14>K14,B14-K14,0) | M14: ==Information!C | N14: ==IF(L14>0,PI()*((C14/2000)^2)*L14*M14*1000,"") | O14: ==IF(L14>0,PI()*((F14/2000)^2)*L14*M14*1000,"")
A15: BH_013 | B15: ==IF(ISREF(Sheet13!A2),MAX(Sheet13!A:A),"") | C15: ==IF(ISREF(Sheet13!B2),AVERAGE(Sheet13!B:B),"") | D15: ==IF(ISREF(Sheet13!B2),MIN(Sheet13!B:B),"") | E15: ==IF(ISREF(Sheet13!B2),MAX(Sheet13!B:B),"") | F15: ==Information!C | G15: ==IF(C15>0,((C15-F15)/F15)*100,"") | H15: ==IF(D15>0,D15-F15,"") | I15: ==IF(C15>0,C15-F15,"") | J15: ==IF(E15>0,E15-F15,"") | K15: ==Information!C | L15: ==IF(B15>K15,B15-K15,0) | M15: ==Information!C | N15: ==IF(L15>0,PI()*((C15/2000)^2)*L15*M15*1000,"") | O15: ==IF(L15>0,PI()*((F15/2000)^2)*L15*M15*1000,"")
A16: BH_014 | B16: ==IF(ISREF(Sheet14!A2),MAX(Sheet14!A:A),"") | C16: ==IF(ISREF(Sheet14!B2),AVERAGE(Sheet14!B:B),"") | D16: ==IF(ISREF(Sheet14!B2),MIN(Sheet14!B:B),"") | E16: ==IF(ISREF(Sheet14!B2),MAX(Sheet14!B:B),"") | F16: ==Information!C | G16: ==IF(C16>0,((C16-F16)/F16)*100,"") | H16: ==IF(D16>0,D16-F16,"") | I16: ==IF(C16>0,C16-F16,"") | J16: ==IF(E16>0,E16-F16,"") | K16: ==Information!C | L16: ==IF(B16>K16,B16-K16,0) | M16: ==Information!C | N16: ==IF(L16>0,PI()*((C16/2000)^2)*L16*M16*1000,"") | O16: ==IF(L16>0,PI()*((F16/2000)^2)*L16*M16*1000,"")
A17: BH_015 | B17: ==IF(ISREF(Sheet15!A2),MAX(Sheet15!A:A),"") | C17: ==IF(ISREF(Sheet15!B2),AVERAGE(Sheet15!B:B),"") | D17: ==IF(ISREF(Sheet15!B2),MIN(Sheet15!B:B),"") | E17: ==IF(ISREF(Sheet15!B2),MAX(Sheet15!B:B),"") | F17: ==Information!C | G17: ==IF(C17>0,((C17-F17)/F17)*100,"") | H17: ==IF(D17>0,D17-F17,"") | I17: ==IF(C17>0,C17-F17,"") | J17: ==IF(E17>0,E17-F17,"") | K17: ==Information!C | L17: ==IF(B17>K17,B17-K17,0) | M17: ==Information!C | N17: ==IF(L17>0,PI()*((C17/2000)^2)*L17*M17*1000,"") | O17: ==IF(L17>0,PI()*((F17/2000)^2)*L17*M17*1000,"")
A18: BH_016 | B18: ==IF(ISREF(Sheet16!A2),MAX(Sheet16!A:A),"") | C18: ==IF(ISREF(Sheet16!B2),AVERAGE(Sheet16!B:B),"") | D18: ==IF(ISREF(Sheet16!B2),MIN(Sheet16!B:B),"") | E18: ==IF(ISREF(Sheet16!B2),MAX(Sheet16!B:B),"") | F18: ==Information!C | G18: ==IF(C18>0,((C18-F18)/F18)*100,"") | H18: ==IF(D18>0,D18-F18,"") | I18: ==IF(C18>0,C18-F18,"") | J18: ==IF(E18>0,E18-F18,"") | K18: ==Information!C | L18: ==IF(B18>K18,B18-K18,0) | M18: ==Information!C | N18: ==IF(L18>0,PI()*((C18/2000)^2)*L18*M18*1000,"") | O18: ==IF(L18>0,PI()*((F18/2000)^2)*L18*M18*1000,"")
A19: BH_017 | B19: ==IF(ISREF(Sheet17!A2),MAX(Sheet17!A:A),"") | C19: ==IF(ISREF(Sheet17!B2),AVERAGE(Sheet17!B:B),"") | D19: ==IF(ISREF(Sheet17!B2),MIN(Sheet17!B:B),"") | E19: ==IF(ISREF(Sheet17!B2),MAX(Sheet17!B:B),"") | F19: ==Information!C | G19: ==IF(C19>0,((C19-F19)/F19)*100,"") | H19: ==IF(D19>0,D19-F19,"") | I19: ==IF(C19>0,C19-F19,"") | J19: ==IF(E19>0,E19-F19,"") | K19: ==Information!C | L19: ==IF(B19>K19,B19-K19,0) | M19: ==Information!C | N19: ==IF(L19>0,PI()*((C19/2000)^2)*L19*M19*1000,"") | O19: ==IF(L19>0,PI()*((F19/2000)^2)*L19*M19*1000,"")
A20: BH_018 | B20: ==IF(ISREF(Sheet18!A2),MAX(Sheet18!A:A),"") | C20: ==IF(ISREF(Sheet18!B2),AVERAGE(Sheet18!B:B),"") | D20: ==IF(ISREF(Sheet18!B2),MIN(Sheet18!B:B),"") | E20: ==IF(ISREF(Sheet18!B2),MAX(Sheet18!B:B),"") | F20: ==Information!C | G20: ==IF(C20>0,((C20-F20)/F20)*100,"") | H20: ==IF(D20>0,D20-F20,"") | I20: ==IF(C20>0,C20-F20,"") | J20: ==IF(E20>0,E20-F20,"") | K20: ==Information!C | L20: ==IF(B20>K20,B20-K20,0) | M20: ==Information!C | N20: ==IF(L20>0,PI()*((C20/2000)^2)*L20*M20*1000,"") | O20: ==IF(L20>0,PI()*((F20/2000)^2)*L20*M20*1000,"")
A21: BH_019 | B21: ==IF(ISREF(Sheet19!A2),MAX(Sheet19!A:A),"") | C21: ==IF(ISREF(Sheet19!B2),AVERAGE(Sheet19!B:B),"") | D21: ==IF(ISREF(Sheet19!B2),MIN(Sheet19!B:B),"") | E21: ==IF(ISREF(Sheet19!B2),MAX(Sheet19!B:B),"") | F21: ==Information!C | G21: ==IF(C21>0,((C21-F21)/F21)*100,"") | H21: ==IF(D21>0,D21-F21,"") | I21: ==IF(C21>0,C21-F21,"") | J21: ==IF(E21>0,E21-F21,"") | K21: ==Information!C | L21: ==IF(B21>K21,B21-K21,0) | M21: ==Information!C | N21: ==IF(L21>0,PI()*((C21/2000)^2)*L21*M21*1000,"") | O21: ==IF(L21>0,PI()*((F21/2000)^2)*L21*M21*1000,"")
A22: BH_020 | B22: ==IF(ISREF(Sheet20!A2),MAX(Sheet20!A:A),"") | C22: ==IF(ISREF(Sheet20!B2),AVERAGE(Sheet20!B:B),"") | D22: ==IF(ISREF(Sheet20!B2),MIN(Sheet20!B:B),"") | E22: ==IF(ISREF(Sheet20!B2),MAX(Sheet20!B:B),"") | F22: ==Information!C | G22: ==IF(C22>0,((C22-F22)/F22)*100,"") | H22: ==IF(D22>0,D22-F22,"") | I22: ==IF(C22>0,C22-F22,"") | J22: ==IF(E22>0,E22-F22,"") | K22: ==Information!C | L22: ==IF(B22>K22,B22-K22,0) | M22: ==Information!C | N22: ==IF(L22>0,PI()*((C22/2000)^2)*L22*M22*1000,"") | O22: ==IF(L22>0,PI()*((F22/2000)^2)*L22*M22*1000,"")
A23: BH_021 | B23: ==IF(ISREF(Sheet21!A2),MAX(Sheet21!A:A),"") | C23: ==IF(ISREF(Sheet21!B2),AVERAGE(Sheet21!B:B),"") | D23: ==IF(ISREF(Sheet21!B2),MIN(Sheet21!B:B),"") | E23: ==IF(ISREF(Sheet21!B2),MAX(Sheet21!B:B),"") | F23: ==Information!C | G23: ==IF(C23>0,((C23-F23)/F23)*100,"") | H23: ==IF(D23>0,D23-F23,"") | I23: ==IF(C23>0,C23-F23,"") | J23: ==IF(E23>0,E23-F23,"") | K23: ==Information!C | L23: ==IF(B23>K23,B23-K23,0) | M23: ==Information!C | N23: ==IF(L23>0,PI()*((C23/2000)^2)*L23*M23*1000,"") | O23: ==IF(L23>0,PI()*((F23/2000)^2)*L23*M23*1000,"")
A24: BH_022 | B24: ==IF(ISREF(Sheet22!A2),MAX(Sheet22!A:A),"") | C24: ==IF(ISREF(Sheet22!B2),AVERAGE(Sheet22!B:B),"") | D24: ==IF(ISREF(Sheet22!B2),MIN(Sheet22!B:B),"") | E24: ==IF(ISREF(Sheet22!B2),MAX(Sheet22!B:B),"") | F24: ==Information!C | G24: ==IF(C24>0,((C24-F24)/F24)*100,"") | H24: ==IF(D24>0,D24-F24,"") | I24: ==IF(C24>0,C24-F24,"") | J24: ==IF(E24>0,E24-F24,"") | K24: ==Information!C | L24: ==IF(B24>K24,B24-K24,0) | M24: ==Information!C | N24: ==IF(L24>0,PI()*((C24/2000)^2)*L24*M24*1000,"") | O24: ==IF(L24>0,PI()*((F24/2000)^2)*L24*M24*1000,"")
A25: BH_023 | B25: ==IF(ISREF(Sheet23!A2),MAX(Sheet23!A:A),"") | C25: ==IF(ISREF(Sheet23!B2),AVERAGE(Sheet23!B:B),"") | D25: ==IF(ISREF(Sheet23!B2),MIN(Sheet23!B:B),"") | E25: ==IF(ISREF(Sheet23!B2),MAX(Sheet23!B:B),"") | F25: ==Information!C | G25: ==IF(C25>0,((C25-F25)/F25)*100,"") | H25: ==IF(D25>0,D25-F25,"") | I25: ==IF(C25>0,C25-F25,"") | J25: ==IF(E25>0,E25-F25,"") | K25: ==Information!C | L25: ==IF(B25>K25,B25-K25,0) | M25: ==Information!C | N25: ==IF(L25>0,PI()*((C25/2000)^2)*L25*M25*1000,"") | O25: ==IF(L25>0,PI()*((F25/2000)^2)*L25*M25*1000,"")
A26: BH_024 | B26: ==IF(ISREF(Sheet24!A2),MAX(Sheet24!A:A),"") | C26: ==IF(ISREF(Sheet24!B2),AVERAGE(Sheet24!B:B),"") | D26: ==IF(ISREF(Sheet24!B2),MIN(Sheet24!B:B),"") | E26: ==IF(ISREF(Sheet24!B2),MAX(Sheet24!B:B),"") | F26: ==Information!C | G26: ==IF(C26>0,((C26-F26)/F26)*100,"") | H26: ==IF(D26>0,D26-F26,"") | I26: ==IF(C26>0,C26-F26,"") | J26: ==IF(E26>0,E26-F26,"") | K26: ==Information!C | L26: ==IF(B26>K26,B26-K26,0) | M26: ==Information!C | N26: ==IF(L26>0,PI()*((C26/2000)^2)*L26*M26*1000,"") | O26: ==IF(L26>0,PI()*((F26/2000)^2)*L26*M26*1000,"")
A27: BH_025 | B27: ==IF(ISREF(Sheet25!A2),MAX(Sheet25!A:A),"") | C27: ==IF(ISREF(Sheet25!B2),AVERAGE(Sheet25!B:B),"") | D27: ==IF(ISREF(Sheet25!B2),MIN(Sheet25!B:B),"") | E27: ==IF(ISREF(Sheet25!B2),MAX(Sheet25!B:B),"") | F27: ==Information!C | G27: ==IF(C27>0,((C27-F27)/F27)*100,"") | H27: ==IF(D27>0,D27-F27,"") | I27: ==IF(C27>0,C27-F27,"") | J27: ==IF(E27>0,E27-F27,"") | K27: ==Information!C | L27: ==IF(B27>K27,B27-K27,0) | M27: ==Information!C | N27: ==IF(L27>0,PI()*((C27/2000)^2)*L27*M27*1000,"") | O27: ==IF(L27>0,PI()*((F27/2000)^2)*L27*M27*1000,"")
A28: BH_026 | B28: ==IF(ISREF(Sheet26!A2),MAX(Sheet26!A:A),"") | C28: ==IF(ISREF(Sheet26!B2),AVERAGE(Sheet26!B:B),"") | D28: ==IF(ISREF(Sheet26!B2),MIN(Sheet26!B:B),"") | E28: ==IF(ISREF(Sheet26!B2),MAX(Sheet26!B:B),"") | F28: ==Information!C | G28: ==IF(C28>0,((C28-F28)/F28)*100,"") | H28: ==IF(D28>0,D28-F28,"") | I28: ==IF(C28>0,C28-F28,"") | J28: ==IF(E28>0,E28-F28,"") | K28: ==Information!C | L28: ==IF(B28>K28,B28-K28,0) | M28: ==Information!C | N28: ==IF(L28>0,PI()*((C28/2000)^2)*L28*M28*1000,"") | O28: ==IF(L28>0,PI()*((F28/2000)^2)*L28*M28*1000,"")
A29: BH_027 | B29: ==IF(ISREF(Sheet27!A2),MAX(Sheet27!A:A),"") | C29: ==IF(ISREF(Sheet27!B2),AVERAGE(Sheet27!B:B),"") | D29: ==IF(ISREF(Sheet27!B2),MIN(Sheet27!B:B),"") | E29: ==IF(ISREF(Sheet27!B2),MAX(Sheet27!B:B),"") | F29: ==Information!C | G29: ==IF(C29>0,((C29-F29)/F29)*100,"") | H29: ==IF(D29>0,D29-F29,"") | I29: ==IF(C29>0,C29-F29,"") | J29: ==IF(E29>0,E29-F29,"") | K29: ==Information!C | L29: ==IF(B29>K29,B29-K29,0) | M29: ==Information!C | N29: ==IF(L29>0,PI()*((C29/2000)^2)*L29*M29*1000,"") | O29: ==IF(L29>0,PI()*((F29/2000)^2)*L29*M29*1000,"")
A30: BH_028 | B30: ==IF(ISREF(Sheet28!A2),MAX(Sheet28!A:A),"") | C30: ==IF(ISREF(Sheet28!B2),AVERAGE(Sheet28!B:B),"") | D30: ==IF(ISREF(Sheet28!B2),MIN(Sheet28!B:B),"") | E30: ==IF(ISREF(Sheet28!B2),MAX(Sheet28!B:B),"") | F30: ==Information!C | G30: ==IF(C30>0,((C30-F30)/F30)*100,"") | H30: ==IF(D30>0,D30-F30,"") | I30: ==IF(C30>0,C30-F30,"") | J30: ==IF(E30>0,E30-F30,"") | K30: ==Information!C | L30: ==IF(B30>K30,B30-K30,0) | M30: ==Information!C | N30: ==IF(L30>0,PI()*((C30/2000)^2)*L30*M30*1000,"") | O30: ==IF(L30>0,PI()*((F30/2000)^2)*L30*M30*1000,"")
A31: BH_029 | B31: ==IF(ISREF(Sheet29!A2),MAX(Sheet29!A:A),"") | C31: ==IF(ISREF(Sheet29!B2),AVERAGE(Sheet29!B:B),"") | D31: ==IF(ISREF(Sheet29!B2),MIN(Sheet29!B:B),"") | E31: ==IF(ISREF(Sheet29!B2),MAX(Sheet29!B:B),"") | F31: ==Information!C | G31: ==IF(C31>0,((C31-F31)/F31)*100,"") | H31: ==IF(D31>0,D31-F31,"") | I31: ==IF(C31>0,C31-F31,"") | J31: ==IF(E31>0,E31-F31,"") | K31: ==Information!C | L31: ==IF(B31>K31,B31-K31,0) | M31: ==Information!C | N31: ==IF(L31>0,PI()*((C31/2000)^2)*L31*M31*1000,"") | O31: ==IF(L31>0,PI()*((F31/2000)^2)*L31*M31*1000,"")
A32: BH_030 | B32: ==IF(ISREF(Sheet30!A2),MAX(Sheet30!A:A),"") | C32: ==IF(ISREF(Sheet30!B2),AVERAGE(Sheet30!B:B),"") | D32: ==IF(ISREF(Sheet30!B2),MIN(Sheet30!B:B),"") | E32: ==IF(ISREF(Sheet30!B2),MAX(Sheet30!B:B),"") | F32: ==Information!C | G32: ==IF(C32>0,((C32-F32)/F32)*100,"") | H32: ==IF(D32>0,D32-F32,"") | I32: ==IF(C32>0,C32-F32,"") | J32: ==IF(E32>0,E32-F32,"") | K32: ==Information!C | L32: ==IF(B32>K32,B32-K32,0) | M32: ==Information!C | N32: ==IF(L32>0,PI()*((C32/2000)^2)*L32*M32*1000,"") | O32: ==IF(L32>0,PI()*((F32/2000)^2)*L32*M32*1000,"")
A33: BH_031 | B33: ==IF(ISREF(Sheet31!A2),MAX(Sheet31!A:A),"") | C33: ==IF(ISREF(Sheet31!B2),AVERAGE(Sheet31!B:B),"") | D33: ==IF(ISREF(Sheet31!B2),MIN(Sheet31!B:B),"") | E33: ==IF(ISREF(Sheet31!B2),MAX(Sheet31!B:B),"") | F33: ==Information!C | G33: ==IF(C33>0,((C33-F33)/F33)*100,"") | H33: ==IF(D33>0,D33-F33,"") | I33: ==IF(C33>0,C33-F33,"") | J33: ==IF(E33>0,E33-F33,"") | K33: ==Information!C | L33: ==IF(B33>K33,B33-K33,0) | M33: ==Information!C | N33: ==IF(L33>0,PI()*((C33/2000)^2)*L33*M33*1000,"") | O33: ==IF(L33>0,PI()*((F33/2000)^2)*L33*M33*1000,"")
A34: BH_032 | B34: ==IF(ISREF(Sheet32!A2),MAX(Sheet32!A:A),"") | C34: ==IF(ISREF(Sheet32!B2),AVERAGE(Sheet32!B:B),"") | D34: ==IF(ISREF(Sheet32!B2),MIN(Sheet32!B:B),"") | E34: ==IF(ISREF(Sheet32!B2),MAX(Sheet32!B:B),"") | F34: ==Information!C | G34: ==IF(C34>0,((C34-F34)/F34)*100,"") | H34: ==IF(D34>0,D34-F34,"") | I34: ==IF(C34>0,C34-F34,"") | J34: ==IF(E34>0,E34-F34,"") | K34: ==Information!C | L34: ==IF(B34>K34,B34-K34,0) | M34: ==Information!C | N34: ==IF(L34>0,PI()*((C34/2000)^2)*L34*M34*1000,"") | O34: ==IF(L34>0,PI()*((F34/2000)^2)*L34*M34*1000,"")
A35: BH_033 | B35: ==IF(ISREF(Sheet33!A2),MAX(Sheet33!A:A),"") | C35: ==IF(ISREF(Sheet33!B2),AVERAGE(Sheet33!B:B),"") | D35: ==IF(ISREF(Sheet33!B2),MIN(Sheet33!B:B),"") | E35: ==IF(ISREF(Sheet33!B2),MAX(Sheet33!B:B),"") | F35: ==Information!C | G35: ==IF(C35>0,((C35-F35)/F35)*100,"") | H35: ==IF(D35>0,D35-F35,"") | I35: ==IF(C35>0,C35-F35,"") | J35: ==IF(E35>0,E35-F35,"") | K35: ==Information!C | L35: ==IF(B35>K35,B35-K35,0) | M35: ==Information!C | N35: ==IF(L35>0,PI()*((C35/2000)^2)*L35*M35*1000,"") | O35: ==IF(L35>0,PI()*((F35/2000)^2)*L35*M35*1000,"")
A36: BH_034 | B36: ==IF(ISREF(Sheet34!A2),MAX(Sheet34!A:A),"") | C36: ==IF(ISREF(Sheet34!B2),AVERAGE(Sheet34!B:B),"") | D36: ==IF(ISREF(Sheet34!B2),MIN(Sheet34!B:B),"") | E36: ==IF(ISREF(Sheet34!B2),MAX(Sheet34!B:B),"") | F36: ==Information!C | G36: ==IF(C36>0,((C36-F36)/F36)*100,"") | H36: ==IF(D36>0,D36-F36,"") | I36: ==IF(C36>0,C36-F36,"") | J36: ==IF(E36>0,E36-F36,"") | K36: ==Information!C | L36: ==IF(B36>K36,B36-K36,0) | M36: ==Information!C | N36: ==IF(L36>0,PI()*((C36/2000)^2)*L36*M36*1000,"") | O36: ==IF(L36>0,PI()*((F36/2000)^2)*L36*M36*1000,"")
A37: BH_035 | B37: ==IF(ISREF(Sheet35!A2),MAX(Sheet35!A:A),"") | C37: ==IF(ISREF(Sheet35!B2),AVERAGE(Sheet35!B:B),"") | D37: ==IF(ISREF(Sheet35!B2),MIN(Sheet35!B:B),"") | E37: ==IF(ISREF(Sheet35!B2),MAX(Sheet35!B:B),"") | F37: ==Information!C | G37: ==IF(C37>0,((C37-F37)/F37)*100,"") | H37: ==IF(D37>0,D37-F37,"") | I37: ==IF(C37>0,C37-F37,"") | J37: ==IF(E37>0,E37-F37,"") | K37: ==Information!C | L37: ==IF(B37>K37,B37-K37,0) | M37: ==Information!C | N37: ==IF(L37>0,PI()*((C37/2000)^2)*L37*M37*1000,"") | O37: ==IF(L37>0,PI()*((F37/2000)^2)*L37*M37*1000,"")
A38: BH_036 | B38: ==IF(ISREF(Sheet36!A2),MAX(Sheet36!A:A),"") | C38: ==IF(ISREF(Sheet36!B2),AVERAGE(Sheet36!B:B),"") | D38: ==IF(ISREF(Sheet36!B2),MIN(Sheet36!B:B),"") | E38: ==IF(ISREF(Sheet36!B2),MAX(Sheet36!B:B),"") | F38: ==Information!C | G38: ==IF(C38>0,((C38-F38)/F38)*100,"") | H38: ==IF(D38>0,D38-F38,"") | I38: ==IF(C38>0,C38-F38,"") | J38: ==IF(E38>0,E38-F38,"") | K38: ==Information!C | L38: ==IF(B38>K38,B38-K38,0) | M38: ==Information!C | N38: ==IF(L38>0,PI()*((C38/2000)^2)*L38*M38*1000,"") | O38: ==IF(L38>0,PI()*((F38/2000)^2)*L38*M38*1000,"")
A39: BH_037 | B39: ==IF(ISREF(Sheet37!A2),MAX(Sheet37!A:A),"") | C39: ==IF(ISREF(Sheet37!B2),AVERAGE(Sheet37!B:B),"") | D39: ==IF(ISREF(Sheet37!B2),MIN(Sheet37!B:B),"") | E39: ==IF(ISREF(Sheet37!B2),MAX(Sheet37!B:B),"") | F39: ==Information!C | G39: ==IF(C39>0,((C39-F39)/F39)*100,"") | H39: ==IF(D39>0,D39-F39,"") | I39: ==IF(C39>0,C39-F39,"") | J39: ==IF(E39>0,E39-F39,"") | K39: ==Information!C | L39: ==IF(B39>K39,B39-K39,0) | M39: ==Information!C | N39: ==IF(L39>0,PI()*((C39/2000)^2)*L39*M39*1000,"") | O39: ==IF(L39>0,PI()*((F39/2000)^2)*L39*M39*1000,"")
A40: BH_038 | B40: ==IF(ISREF(Sheet38!A2),MAX(Sheet38!A:A),"") | C40: ==IF(ISREF(Sheet38!B2),AVERAGE(Sheet38!B:B),"") | D40: ==IF(ISREF(Sheet38!B2),MIN(Sheet38!B:B),"") | E40: ==IF(ISREF(Sheet38!B2),MAX(Sheet38!B:B),"") | F40: ==Information!C | G40: ==IF(C40>0,((C40-F40)/F40)*100,"") | H40: ==IF(D40>0,D40-F40,"") | I40: ==IF(C40>0,C40-F40,"") | J40: ==IF(E40>0,E40-F40,"") | K40: ==Information!C | L40: ==IF(B40>K40,B40-K40,0) | M40: ==Information!C | N40: ==IF(L40>0,PI()*((C40/2000)^2)*L40*M40*1000,"") | O40: ==IF(L40>0,PI()*((F40/2000)^2)*L40*M40*1000,"")
...

Sheet Graphs
A1: Borehole Caliper Graphs & Plots

Sheet Sheet1
A1: Depth | B1: Diameter | C1: Radius | D1: -Radius | E1: Planned Rad | F1: -Planned Rad | G1: Planned Diam | H1: Difference | L1: Hole_1

Sheet Sheet2
A1: Depth | B1: Diameter | C1: Radius | D1: -Radius | E1: Planned Rad | F1: -Planned Rad | G1: Planned Diam | H1: Difference | L1: Hole_2

Sheet Sheet3
A1: Depth | B1: Diameter | C1: Radius | D1: -Radius | E1: Planned Rad | F1: -Planned Rad | G1: Planned Diam | H1: Difference | L1: Hole_3

Sheet Sheet4
A1: Depth | B1: Diameter | C1: Radius | D1: -Radius | E1: Planned Rad | F1: -Planned Rad | G1: Planned Diam | H1: Difference | L1: Hole_4

Sheet Sheet5
A1: Depth | B1: Diameter | C1: Radius | D1: -Radius | E1: Planned Rad | F1: -Planned Rad | G1: Planned Diam | H1: Difference | L1: Hole_5

Sheet Sheet6
A1: Depth | B1: Diameter | C1: Radius | D1: -Radius | E1: Planned Rad | F1: -Planned Rad | G1: Planned Diam | H1: Difference | L1: Hole_6

Sheet Sheet7
A1: Depth | B1: Diameter | C1: Radius | D1: -Radius | E1: Planned Rad | F1: -Planned Rad | G1: Planned Diam | H1: Difference | L1: Hole_7

Sheet Sheet8
A1: Depth | B1: Diameter | C1: Radius | D1: -Radius | E1: Planned Rad | F1: -Planned Rad | G1: Planned Diam | H1: Difference | L1: Hole_8

Sheet Sheet9
A1: Depth | B1: Diameter | C1: Radius | D1: -Radius | E1: Planned Rad | F1: -Planned Rad | G1: Planned Diam | H1: Difference | L1: Hole_9

Sheet Sheet10
A1: Depth | B1: Diameter | C1: Radius | D1: -Radius | E1: Planned Rad | F1: -Planned Rad | G1: Planned Diam | H1: Difference | L1: Hole_10

Sheet Sheet11
A1: Depth | B1: Diameter | C1: Radius | D1: -Radius | E1: Planned Rad | F1: -Planned Rad | G1: Planned Diam | H1: Difference | L1: Hole_11

Sheet Sheet12
A1: Depth | B1: Diameter | C1: Radius | D1: -Radius | E1: Planned Rad | F1: -Planned Rad | G1: Planned Diam | H1: Difference | L1: Hole_12

Sheet Sheet13
A1: Depth | B1: Diameter | C1: Radius | D1: -Radius | E1: Planned Rad | F1: -Planned Rad | G1: Planned Diam | H1: Difference | L1: Hole_13

Sheet Sheet14
A1: Depth | B1: Diameter | C1: Radius | D1: -Radius | E1: Planned Rad | F1: -Planned Rad | G1: Planned Diam | H1: Difference | L1: Hole_14

Sheet Sheet15
A1: Depth | B1: Diameter | C1: Radius | D1: -Radius | E1: Planned Rad | F1: -Planned Rad | G1: Planned Diam | H1: Difference | L1: Hole_15

Sheet Sheet16
A1: Depth | B1: Diameter | C1: Radius | D1: -Radius | E1: Planned Rad | F1: -Planned Rad | G1: Planned Diam | H1: Difference | L1: Hole_16

Sheet Sheet17
A1: Depth | B1: Diameter | C1: Radius | D1: -Radius | E1: Planned Rad | F1: -Planned Rad | G1: Planned Diam | H1: Difference | L1: Hole_17

Sheet Sheet18
A1: Depth | B1: Diameter | C1: Radius | D1: -Radius | E1: Planned Rad | F1: -Planned Rad | G1: Planned Diam | H1: Difference | L1: Hole_18

Sheet Sheet19
A1: Depth | B1: Diameter | C1: Radius | D1: -Radius | E1: Planned Rad | F1: -Planned Rad | G1: Planned Diam | H1: Difference | L1: Hole_19

Sheet Sheet20
A1: Depth | B1: Diameter | C1: Radius | D1: -Radius | E1: Planned Rad | F1: -Planned Rad | G1: Planned Diam | H1: Difference | L1: Hole_20

Sheet Sheet21
A1: Depth | B1: Diameter | C1: Radius | D1: -Radius | E1: Planned Rad | F1: -Planned Rad | G1: Planned Diam | H1: Difference | L1: Hole_21

Sheet Sheet22
A1: Depth | B1: Diameter | C1: Radius | D1: -Radius | E1: Planned Rad | F1: -Planned Rad | G1: Planned Diam | H1: Difference | L1: Hole_22

Sheet Sheet23
A1: Depth | B1: Diameter | C1: Radius | D1: -Radius | E1: Planned Rad | F1: -Planned Rad | G1: Planned Diam | H1: Difference | L1: Hole_23

Sheet Sheet24
A1: Depth | B1: Diameter | C1: Radius | D1: -Radius | E1: Planned Rad | F1: -Planned Rad | G1: Planned Diam | H1: Difference | L1: Hole_24

Sheet Sheet25
A1: Depth | B1: Diameter | C1: Radius | D1: -Radius | E1: Planned Rad | F1: -Planned Rad | G1: Planned Diam | H1: Difference | L1: Hole_25

Sheet Sheet26
A1: Depth | B1: Diameter | C1: Radius | D1: -Radius | E1: Planned Rad | F1: -Planned Rad | G1: Planned Diam | H1: Difference | L1: Hole_26

Sheet Sheet27
A1: Depth | B1: Diameter | C1: Radius | D1: -Radius | E1: Planned Rad | F1: -Planned Rad | G1: Planned Diam | H1: Difference | L1: Hole_27

Sheet Sheet28
A1: Depth | B1: Diameter | C1: Radius | D1: -Radius | E1: Planned Rad | F1: -Planned Rad | G1: Planned Diam | H1: Difference | L1: Hole_28

Sheet Sheet29
A1: Depth | B1: Diameter | C1: Radius | D1: -Radius | E1: Planned Rad | F1: -Planned Rad | G1: Planned Diam | H1: Difference | L1: Hole_29

Sheet Sheet30
A1: Depth | B1: Diameter | C1: Radius | D1: -Radius | E1: Planned Rad | F1: -Planned Rad | G1: Planned Diam | H1: Difference | L1: Hole_30

Sheet Sheet31
A1: Depth | B1: Diameter | C1: Radius | D1: -Radius | E1: Planned Rad | F1: -Planned Rad | G1: Planned Diam | H1: Difference | L1: Hole_31

Sheet Sheet32
A1: Depth | B1: Diameter | C1: Radius | D1: -Radius | E1: Planned Rad | F1: -Planned Rad | G1: Planned Diam | H1: Difference | L1: Hole_32

Sheet Sheet33
A1: Depth | B1: Diameter | C1: Radius | D1: -Radius | E1: Planned Rad | F1: -Planned Rad | G1: Planned Diam | H1: Difference | L1: Hole_33

Sheet Sheet34
A1: Depth | B1: Diameter | C1: Radius | D1: -Radius | E1: Planned Rad | F1: -Planned Rad | G1: Planned Diam | H1: Difference | L1: Hole_34

Sheet Sheet35
A1: Depth | B1: Diameter | C1: Radius | D1: -Radius | E1: Planned Rad | F1: -Planned Rad | G1: Planned Diam | H1: Difference | L1: Hole_35

Sheet Sheet36
A1: Depth | B1: Diameter | C1: Radius | D1: -Radius | E1: Planned Rad | F1: -Planned Rad | G1: Planned Diam | H1: Difference | L1: Hole_36

Sheet Sheet37
A1: Depth | B1: Diameter | C1: Radius | D1: -Radius | E1: Planned Rad | F1: -Planned Rad | G1: Planned Diam | H1: Difference | L1: Hole_37

Sheet Sheet38
A1: Depth | B1: Diameter | C1: Radius | D1: -Radius | E1: Planned Rad | F1: -Planned Rad | G1: Planned Diam | H1: Difference | L1: Hole_38

Sheet Sheet39
A1: Depth | B1: Diameter | C1: Radius | D1: -Radius | E1: Planned Rad | F1: -Planned Rad | G1: Planned Diam | H1: Difference | L1: Hole_39

Sheet Sheet40
A1: Depth | B1: Diameter | C1: Radius | D1: -Radius | E1: Planned Rad | F1: -Planned Rad | G1: Planned Diam | H1: Difference | L1: Hole_40

Sheet Sheet41
A1: Depth | B1: Diameter | C1: Radius | D1: -Radius | E1: Planned Rad | F1: -Planned Rad | G1: Planned Diam | H1: Difference | L1: Hole_41

Sheet Sheet42
A1: Depth | B1: Diameter | C1: Radius | D1: -Radius | E1: Planned Rad | F1: -Planned Rad | G1: Planned Diam | H1: Difference | L1: Hole_42

Sheet Sheet43
A1: Depth | B1: Diameter | C1: Radius | D1: -Radius | E1: Planned Rad | F1: -Planned Rad | G1: Planned Diam | H1: Difference | L1: Hole_43

Sheet Sheet44
A1: Depth | B1: Diameter | C1: Radius | D1: -Radius | E1: Planned Rad | F1: -Planned Rad | G1: Planned Diam | H1: Difference | L1: Hole_44

Sheet Sheet45
A1: Depth | B1: Diameter | C1: Radius | D1: -Radius | E1: Planned Rad | F1: -Planned Rad | G1: Planned Diam | H1: Difference | L1: Hole_45

Sheet Sheet46
A1: Depth | B1: Diameter | C1: Radius | D1: -Radius | E1: Planned Rad | F1: -Planned Rad | G1: Planned Diam | H1: Difference | L1: Hole_46

Sheet Sheet47
A1: Depth | B1: Diameter | C1: Radius | D1: -Radius | E1: Planned Rad | F1: -Planned Rad | G1: Planned Diam | H1: Difference | L1: Hole_47

Sheet Sheet48
A1: Depth | B1: Diameter | C1: Radius | D1: -Radius | E1: Planned Rad | F1: -Planned Rad | G1: Planned Diam | H1: Difference | L1: Hole_48

Sheet Sheet49
A1: Depth | B1: Diameter | C1: Radius | D1: -Radius | E1: Planned Rad | F1: -Planned Rad | G1: Planned Diam | H1: Difference | L1: Hole_49

Sheet Sheet50
A1: Depth | B1: Diameter | C1: Radius | D1: -Radius | E1: Planned Rad | F1: -Planned Rad | G1: Planned Diam | H1: Difference | L1: Hole_50
