Workbook
Name Actual1: OFFSET(Sheet1!$B$2,0,0,COUNTA(Sheet1!$B:$B),-1)
Name Actual10: OFFSET(Sheet10!$B$2,0,0,COUNTA(Sheet10!$B:$B),-1)
Name Actual11: OFFSET(Sheet11!$B$2,0,0,COUNTA(Sheet11!$B:$B),-1)
Name Actual12: OFFSET(Sheet12!$B$2,0,0,COUNTA(Sheet12!$B:$B),-1)
Name Actual13: OFFSET(Sheet13!$B$2,0,0,COUNTA(Sheet13!$B:$B),-1)
Name Actual14: OFFSET(Sheet14!$B$2,0,0,COUNTA(Sheet14!$B:$B),-1)
Name Actual15: OFFSET(Sheet15!$B$2,0,0,COUNTA(Sheet15!$B:$B),-1)
Name Actual16: OFFSET(Sheet16!$B$2,0,0,COUNTA(Sheet16!$B:$B),-1)
Name Actual17: OFFSET(Sheet17!$B$2,0,0,COUNTA(Sheet17!$B:$B),-1)
Name Actual18: OFFSET(Sheet18!$B$2,0,0,COUNTA(Sheet18!$B:$B),-1)
Name Actual19: OFFSET(Sheet19!$B$2,0,0,COUNTA(Sheet19!$B:$B),-1)
Name Actual2: OFFSET(Sheet2!$B$2,0,0,COUNTA(Sheet2!$B:$B),-1)
Name Actual20: OFFSET(Sheet20!$B$2,0,0,COUNTA(Sheet20!$B:$B),-1)
Name Actual21: OFFSET(Sheet21!$B$2,0,0,COUNTA(Sheet21!$B:$B),-1)
Name Actual22: OFFSET(Sheet22!$B$2,0,0,COUNTA(Sheet22!$B:$B),-1)
Name Actual23: OFFSET(Sheet23!$B$2,0,0,COUNTA(Sheet23!$B:$B),-1)
Name Actual24: OFFSET(Sheet24!$B$2,0,0,COUNTA(Sheet24!$B:$B),-1)
Name Actual25: OFFSET(Sheet25!$B$2,0,0,COUNTA(Sheet25!$B:$B),-1)
Name Actual26: OFFSET(Sheet26!$B$2,0,0,COUNTA(Sheet26!$B:$B),-1)
Name Actual27: OFFSET(Sheet27!$B$2,0,0,COUNTA(Sheet27!$B:$B),-1)
Name Actual28: OFFSET(Sheet28!$B$2,0,0,COUNTA(Sheet28!$B:$B),-1)
Name Actual29: OFFSET(Sheet29!$B$2,0,0,COUNTA(Sheet29!$B:$B),-1)
Name Actual3: OFFSET(Sheet3!$B$2,0,0,COUNTA(Sheet3!$B:$B),-1)
Name Actual30: OFFSET(Sheet30!$B$2,0,0,COUNTA(Sheet30!$B:$B),-1)
Name Actual31: OFFSET(Sheet31!$B$2,0,0,COUNTA(Sheet31!$B:$B),-1)
Name Actual32: OFFSET(Sheet32!$B$2,0,0,COUNTA(Sheet32!$B:$B),-1)
Name Actual33: OFFSET(Sheet33!$B$2,0,0,COUNTA(Sheet33!$B:$B),-1)
Name Actual34: OFFSET(Sheet34!$B$2,0,0,COUNTA(Sheet34!$B:$B),-1)
Name Actual35: OFFSET(Sheet35!$B$2,0,0,COUNTA(Sheet35!$B:$B),-1)
Name Actual36: OFFSET(Sheet36!$B$2,0,0,COUNTA(Sheet36!$B:$B),-1)
Name Actual37: OFFSET(Sheet37!$B$2,0,0,COUNTA(Sheet37!$B:$B),-1)
Name Actual38: OFFSET(Sheet38!$B$2,0,0,COUNTA(Sheet38!$B:$B),-1)
Name Actual39: OFFSET(Sheet39!$B$2,0,0,COUNTA(Sheet39!$B:$B),-1)
Name Actual4: OFFSET(Sheet4!$B$2,0,0,COUNTA(Sheet4!$B:$B),-1)
Name Actual40: OFFSET(Sheet40!$B$2,0,0,COUNTA(Sheet40!$B:$B),-1)
Name Actual41: OFFSET(Sheet41!$B$2,0,0,COUNTA(Sheet41!$B:$B),-1)
Name Actual42: OFFSET(Sheet42!$B$2,0,0,COUNTA(Sheet42!$B:$B),-1)
Name Actual43: OFFSET(Sheet43!$B$2,0,0,COUNTA(Sheet43!$B:$B),-1)
Name Actual44: OFFSET(Sheet44!$B$2,0,0,COUNTA(Sheet44!$B:$B),-1)
Name Actual45: OFFSET(Sheet45!$B$2,0,0,COUNTA(Sheet45!$B:$B),-1)
Name Actual46: OFFSET(Sheet46!$B$2,0,0,COUNTA(Sheet46!$B:$B),-1)
Name Actual47: OFFSET(Sheet47!$B$2,0,0,COUNTA(Sheet47!$B:$B),-1)
Name Actual48: OFFSET(Sheet48!$B$2,0,0,COUNTA(Sheet48!$B:$B),-1)
Name Actual49: OFFSET(Sheet49!$B$2,0,0,COUNTA(Sheet49!$B:$B),-1)
Name Actual5: OFFSET(Sheet5!$B$2,0,0,COUNTA(Sheet5!$B:$B),-1)
Name Actual50: OFFSET(Sheet50!$B$2,0,0,COUNTA(Sheet50!$B:$B),-1)
Name Actual6: OFFSET(Sheet6!$B$2,0,0,COUNTA(Sheet6!$B:$B),-1)
Name Actual7: OFFSET(Sheet7!$B$2,0,0,COUNTA(Sheet7!$B:$B),-1)
Name Actual8: OFFSET(Sheet8!$B$2,0,0,COUNTA(Sheet8!$B:$B),-1)
Name Actual9: OFFSET(Sheet9!$B$2,0,0,COUNTA(Sheet9!$B:$B),-1)
Name ActualM1: OFFSET(Sheet1!$D$2,0,0,COUNTA(Sheet1!$D:$D),-1)
Name ActualM10: OFFSET(Sheet10!$D$2,0,0,COUNTA(Sheet10!$D:$D),-1)
Name ActualM11: OFFSET(Sheet11!$D$2,0,0,COUNTA(Sheet11!$D:$D),-1)
Name ActualM12: OFFSET(Sheet12!$D$2,0,0,COUNTA(Sheet12!$D:$D),-1)
Name ActualM13: OFFSET(Sheet13!$D$2,0,0,COUNTA(Sheet13!$D:$D),-1)
Name ActualM14: OFFSET(Sheet14!$D$2,0,0,COUNTA(Sheet14!$D:$D),-1)
Name ActualM15: OFFSET(Sheet15!$D$2,0,0,COUNTA(Sheet15!$D:$D),-1)
Name ActualM16: OFFSET(Sheet16!$D$2,0,0,COUNTA(Sheet16!$D:$D),-1)
Name ActualM17: OFFSET(Sheet17!$D$2,0,0,COUNTA(Sheet17!$D:$D),-1)
Name ActualM18: OFFSET(Sheet18!$D$2,0,0,COUNTA(Sheet18!$D:$D),-1)

Sheet Graphs
A62: =Information!C4-20 -> -20

Sheet Table
B1: Diameter (mm) | F1: Depths (m) | H1: Charge Mass (Kg) | M1: % variations of kg for diameters | P1: Stemming | Q1: =Information!C5 -> 0
A2: BH No. | B2: Minimum | C2: Average | D2: Maximum | E2: Planned | F2: From | G2: to | H2: Minimum | I2: Average | J2: Maximum | K2: Planned | L2: Deviation: Ave vs. Plan | M2: Minimum | N2: Average | O2: Maximum
A3: =Sheet1!L1 -> 0 | B3: =MIN(Sheet1!B2:B5000) -> 0 | C3: =AVERAGE(Sheet1!B2:B5000) -> 0 | D3: =MAX(Sheet1!B2:B5000) -> 0 | E3: =Sheet1!G2 -> 0 | F3: =MIN(Sheet1!A2:A5000) -> 0 | G3: =MAX(Sheet1!A2:A5000) -> 0 | H3: =((G3-$Q$1)*($Q$3*B3^2))/1273 -> 0 | I3: =((G3-$Q$1)*($Q$3*C3^2))/1273 -> 0 | J3: =((G3-$Q$1)*($Q$3*D3^2))/1273 -> 0 | K3: =((G3-$Q$1)*($Q$3*E3^2))/1273 -> 0 | L3: =I3-K3 -> 0 | M3: =((H3/$K3)*100)-100 -> #DIV/0! | N3: =((I3/$K3)*100)-100 -> #DIV/0! | O3: =((J3/$K3)*100)-100 -> #DIV/0! | P3: Inhole density | Q3: =Information!C6 -> 0
A4: =Sheet2!L1 -> 0 | B4: =MIN(Sheet2!B2:B5000) -> 0 | C4: =AVERAGE(Sheet2!B2:B5000) -> 0 | D4: =MAX(Sheet2!B2:B5000) -> 0 | E4: =Sheet2!G2 -> 0 | F4: =MIN(Sheet2!A2:A5000) -> 0 | G4: =MAX(Sheet2!A2:A5000) -> 0 | H4: =((G4-$Q$1)*($Q$3*B4^2))/1273 -> 0 | I4: =((G4-$Q$1)*($Q$3*C4^2))/1273 -> 0 | J4: =((G4-$Q$1)*($Q$3*D4^2))/1273 -> 0 | K4: =((G4-$Q$1)*($Q$3*E4^2))/1273 -> 0 | L4: =I4-K4 -> 0 | M4: =((H4/$K4)*100)-100 -> #DIV/0! | N4: =((I4/$K4)*100)-100 -> #DIV/0! | O4: =((J4/$K4)*100)-100 -> #DIV/0!
A5: =Sheet3!L1 -> 0 | B5: =MIN(Sheet3!B2:B5000) -> 0 | C5: =AVERAGE(Sheet3!B2:B5000) -> 0 | D5: =MAX(Sheet3!B2:B5000) -> 0 | E5: =Sheet3!G2 -> 0 | F5: =MIN(Sheet3!A2:A5000) -> 0 | G5: =MAX(Sheet3!A2:A5000) -> 0 | H5: =((G5-$Q$1)*($Q$3*B5^2))/1273 -> 0 | I5: =((G5-$Q$1)*($Q$3*C5^2))/1273 -> 0 | J5: =((G5-$Q$1)*($Q$3*D5^2))/1273 -> 0 | K5: =((G5-$Q$1)*($Q$3*E5^2))/1273 -> 0 | L5: =I5-K5 -> 0 | M5: =((H5/$K5)*100)-100 -> #DIV/0! | N5: =((I5/$K5)*100)-100 -> #DIV/0! | O5: =((J5/$K5)*100)-100 -> #DIV/0!
A6: =Sheet4!L1 -> 0 | B6: =MIN(Sheet4!B2:B5000) -> 0 | C6: =AVERAGE(Sheet4!B2:B5000) -> 0 | D6: =MAX(Sheet4!B2:B5000) -> 0 | E6: =Sheet4!G2 -> 0 | F6: =MIN(Sheet4!A2:A5000) -> 0 | G6: =MAX(Sheet4!A2:A5000) -> 0 | H6: =((G6-$Q$1)*($Q$3*B6^2))/1273 -> 0 | I6: =((G6-$Q$1)*($Q$3*C6^2))/1273 -> 0 | J6: =((G6-$Q$1)*($Q$3*D6^2))/1273 -> 0 | K6: =((G6-$Q$1)*($Q$3*E6^2))/1273 -> 0 | L6: =I6-K6 -> 0 | M6: =((H6/$K6)*100)-100 -> #DIV/0! | N6: =((I6/$K6)*100)-100 -> #DIV/0! | O6: =((J6/$K6)*100)-100 -> #DIV/0!
A7: =Sheet5!L1 -> 0 | B7: =MIN(Sheet5!B2:B5000) -> 0 | C7: =AVERAGE(Sheet5!B2:B5000) -> 0 | D7: =MAX(Sheet5!B2:B5000) -> 0 | E7: =Sheet5!G2 -> 0 | F7: =MIN(Sheet5!A2:A5000) -> 0 | G7: =MAX(Sheet5!A2:A5000) -> 0 | H7: =((G7-$Q$1)*($Q$3*B7^2))/1273 -> 0 | I7: =((G7-$Q$1)*($Q$3*C7^2))/1273 -> 0 | J7: =((G7-$Q$1)*($Q$3*D7^2))/1273 -> 0 | K7: =((G7-$Q$1)*($Q$3*E7^2))/1273 -> 0 | L7: =I7-K7 -> 0 | M7: =((H7/$K7)*100)-100 -> #DIV/0! | N7: =((I7/$K7)*100)-100 -> #DIV/0! | O7: =((J7/$K7)*100)-100 -> #DIV/0!
A8: =Sheet6!L1 -> 0 | B8: =MIN(Sheet6!B2:B5000) -> 0 | C8: =AVERAGE(Sheet6!B2:B5000) -> 0 | D8: =MAX(Sheet6!B2:B5000) -> 0 | E8: =Sheet6!G2 -> 0 | F8: =MIN(Sheet6!A2:A5000) -> 0 | G8: =MAX(Sheet6!A2:A5000) -> 0 | H8: =((G8-$Q$1)*($Q$3*B8^2))/1273 -> 0 | I8: =((G8-$Q$1)*($Q$3*C8^2))/1273 -> 0 | J8: =((G8-$Q$1)*($Q$3*D8^2))/1273 -> 0 | K8: =((G8-$Q$1)*($Q$3*E8^2))/1273 -> 0 | L8: =I8-K8 -> 0 | M8: =((H8/$K8)*100)-100 -> #DIV/0! | N8: =((I8/$K8)*100)-100 -> #DIV/0! | O8: =((J8/$K8)*100)-100 -> #DIV/0!
A9: =Sheet7!L1 -> 0 | B9: =MIN(Sheet7!B2:B5000) -> 0 | C9: =AVERAGE(Sheet7!B2:B5000) -> 0 | D9: =MAX(Sheet7!B2:B5000) -> 0 | E9: =Sheet7!G2 -> 0 | F9: =MIN(Sheet7!A2:A5000) -> 0 | G9: =MAX(Sheet7!A2:A5000) -> 0 | H9: =((G9-$Q$1)*($Q$3*B9^2))/1273 -> 0 | I9: =((G9-$Q$1)*($Q$3*C9^2))/1273 -> 0 | J9: =((G9-$Q$1)*($Q$3*D9^2))/1273 -> 0 | K9: =((G9-$Q$1)*($Q$3*E9^2))/1273 -> 0 | L9: =I9-K9 -> 0 | M9: =((H9/$K9)*100)-100 -> #DIV/0! | N9: =((I9/$K9)*100)-100 -> #DIV/0! | O9: =((J9/$K9)*100)-100 -> #DIV/0!
A10: =Sheet8!L1 -> 0 | B10: =MIN(Sheet8!B2:B5000) -> 0 | C10: =AVERAGE(Sheet8!B2:B5000) -> 0 | D10: =MAX(Sheet8!B2:B5000) -> 0 | E10: =Sheet8!G2 -> 0 | F10: =MIN(Sheet8!A2:A5000) -> 0 | G10: =MAX(Sheet8!A2:A5000) -> 0 | H10: =((G10-$Q$1)*($Q$3*B10^2))/1273 -> 0 | I10: =((G10-$Q$1)*($Q$3*C10^2))/1273 -> 0 | J10: =((G10-$Q$1)*($Q$3*D10^2))/1273 -> 0 | K10: =((G10-$Q$1)*($Q$3*E10^2))/1273 -> 0 | L10: =I10-K10 -> 0 | M10: =((H10/$K10)*100)-100 -> #DIV/0! | N10: =((I10/$K10)*100)-100 -> #DIV/0! | O10: =((J10/$K10)*100)-100 -> #DIV/0!
A11: =Sheet9!L1 -> 0 | B11: =MIN(Sheet9!B2:B5000) -> 0 | C11: =AVERAGE(Sheet9!B2:B5000) -> 0 | D11: =MAX(Sheet9!B2:B5000) -> 0 | E11: =Sheet9!G2 -> 0 | F11: =MIN(Sheet9!A2:A5000) -> 0 | G11: =MAX(Sheet9!A2:A5000) -> 0 | H11: =((G11-$Q$1)*($Q$3*B11^2))/1273 -> 0 | I11: =((G11-$Q$1)*($Q$3*C11^2))/1273 -> 0 | J11: =((G11-$Q$1)*($Q$3*D11^2))/1273 -> 0 | K11: =((G11-$Q$1)*($Q$3*E11^2))/1273 -> 0 | L11: =I11-K11 -> 0 | M11: =((H11/$K11)*100)-100 -> #DIV/0! | N11: =((I11/$K11)*100)-100 -> #DIV/0! | O11: =((J11/$K11)*100)-100 -> #DIV/0!
A12: =Sheet10!L1 -> 0 | B12: =MIN(Sheet10!B2:B5000) -> 0 | C12: =AVERAGE(Sheet10!B2:B5000) -> 0 | D12: =MAX(Sheet10!B2:B5000) -> 0 | E12: =Sheet10!G2 -> 0 | F12: =MIN(Sheet10!A2:A5000) -> 0 | G12: =MAX(Sheet10!A2:A5000) -> 0 | H12: =((G12-$Q$1)*($Q$3*B12^2))/1273 -> 0 | I12: =((G12-$Q$1)*($Q$3*C12^2))/1273 -> 0 | J12: =((G12-$Q$1)*($Q$3*D12^2))/1273 -> 0 | K12: =((G12-$Q$1)*($Q$3*E12^2))/1273 -> 0 | L12: =I12-K12 -> 0 | M12: =((H12/$K12)*100)-100 -> #DIV/0! | N12: =((I12/$K12)*100)-100 -> #DIV/0! | O12: =((J12/$K12)*100)-100 -> #DIV/0!
A13: =Sheet11!L1 -> 0 | B13: =MIN(Sheet11!B2:B5000) -> 0 | C13: =AVERAGE(Sheet11!B2:B5000) -> 0 | D13: =MAX(Sheet11!B2:B5000) -> 0 | E13: =Sheet11!G2 -> 0 | F13: =MIN(Sheet11!A2:A5000) -> 0 | G13: =MAX(Sheet11!A2:A5000) -> 0 | H13: =((G13-$Q$1)*($Q$3*B13^2))/1273 -> 0 | I13: =((G13-$Q$1)*($Q$3*C13^2))/1273 -> 0 | J13: =((G13-$Q$1)*($Q$3*D13^2))/1273 -> 0 | K13: =((G13-$Q$1)*($Q$3*E13^2))/1273 -> 0 | L13: =I13-K13 -> 0 | M13: =((H13/$K13)*100)-100 -> #DIV/0! | N13: =((I13/$K13)*100)-100 -> #DIV/0! | O13: =((J13/$K13)*100)-100 -> #DIV/0!
A14: =Sheet12!L1 -> 0 | B14: =MIN(Sheet12!B2:B5000) -> 0 | C14: =AVERAGE(Sheet12!B2:B5000) -> 0 | D14: =MAX(Sheet12!B2:B5000) -> 0 | E14: =Sheet12!G2 -> 0 | F14: =MIN(Sheet12!A2:A5000) -> 0 | G14: =MAX(Sheet12!A2:A5000) -> 0 | H14: =((G14-$Q$1)*($Q$3*B14^2))/1273 -> 0 | I14: =((G14-$Q$1)*($Q$3*C14^2))/1273 -> 0 | J14: =((G14-$Q$1)*($Q$3*D14^2))/1273 -> 0 | K14: =((G14-$Q$1)*($Q$3*E14^2))/1273 -> 0 | L14: =I14-K14 -> 0 | M14: =((H14/$K14)*100)-100 -> #DIV/0! | N14: =((I14/$K14)*100)-100 -> #DIV/0! | O14: =((J14/$K14)*100)-100 -> #DIV/0!
A15: =Sheet13!L1 -> 0 | B15: =MIN(Sheet13!B2:B5000) -> 0 | C15: =AVERAGE(Sheet13!B2:B5000) -> 0 | D15: =MAX(Sheet13!B2:B5000) -> 0 | E15: =Sheet13!G2 -> 0 | F15: =MIN(Sheet13!A2:A5000) -> 0 | G15: =MAX(Sheet13!A2:A5000) -> 0 | H15: =((G15-$Q$1)*($Q$3*B15^2))/1273 -> 0 | I15: =((G15-$Q$1)*($Q$3*C15^2))/1273 -> 0 | J15: =((G15-$Q$1)*($Q$3*D15^2))/1273 -> 0 | K15: =((G15-$Q$1)*($Q$3*E15^2))/1273 -> 0 | L15: =I15-K15 -> 0 | M15: =((H15/$K15)*100)-100 -> #DIV/0! | N15: =((I15/$K15)*100)-100 -> #DIV/0! | O15: =((J15/$K15)*100)-100 -> #DIV/0!
A16: =Sheet14!L1 -> 0 | B16: =MIN(Sheet14!B2:B5000) -> 0 | C16: =AVERAGE(Sheet14!B2:B5000) -> 0 | D16: =MAX(Sheet14!B2:B5000) -> 0 | E16: =Sheet14!G2 -> 0 | F16: =MIN(Sheet14!A2:A5000) -> 0 | G16: =MAX(Sheet14!A2:A5000) -> 0 | H16: =((G16-$Q$1)*($Q$3*B16^2))/1273 -> 0 | I16: =((G16-$Q$1)*($Q$3*C16^2))/1273 -> 0 | J16: =((G16-$Q$1)*($Q$3*D16^2))/1273 -> 0 | K16: =((G16-$Q$1)*($Q$3*E16^2))/1273 -> 0 | L16: =I16-K16 -> 0 | M16: =((H16/$K16)*100)-100 -> #DIV/0! | N16: =((I16/$K16)*100)-100 -> #DIV/0! | O16: =((J16/$K16)*100)-100 -> #DIV/0!
A17: =Sheet15!L1 -> 0 | B17: =MIN(Sheet15!B2:B5000) -> 0 | C17: =AVERAGE(Sheet15!B2:B5000) -> 0 | D17: =MAX(Sheet15!B2:B5000) -> 0 | E17: =Sheet15!G2 -> 0 | F17: =MIN(Sheet15!A2:A5000) -> 0 | G17: =MAX(Sheet15!A2:A5000) -> 0 | H17: =((G17-$Q$1)*($Q$3*B17^2))/1273 -> 0 | I17: =((G17-$Q$1)*($Q$3*C17^2))/1273 -> 0 | J17: =((G17-$Q$1)*($Q$3*D17^2))/1273 -> 0 | K17: =((G17-$Q$1)*($Q$3*E17^2))/1273 -> 0 | L17: =I17-K17 -> 0 | M17: =((H17/$K17)*100)-100 -> #DIV/0! | N17: =((I17/$K17)*100)-100 -> #DIV/0! | O17: =((J17/$K17)*100)-100 -> #DIV/0!
A18: =Sheet16!L1 -> 0 | B18: =MIN(Sheet16!B2:B5000) -> 0 | C18: =AVERAGE(Sheet16!B2:B5000) -> 0 | D18: =MAX(Sheet16!B2:B5000) -> 0 | E18: =Sheet16!G2 -> 0 | F18: =MIN(Sheet16!A2:A5000) -> 0 | G18: =MAX(Sheet16!A2:A5000) -> 0 | H18: =((G18-$Q$1)*($Q$3*B18^2))/1273 -> 0 | I18: =((G18-$Q$1)*($Q$3*C18^2))/1273 -> 0 | J18: =((G18-$Q$1)*($Q$3*D18^2))/1273 -> 0 | K18: =((G18-$Q$1)*($Q$3*E18^2))/1273 -> 0 | L18: =I18-K18 -> 0 | M18: =((H18/$K18)*100)-100 -> #DIV/0! | N18: =((I18/$K18)*100)-100 -> #DIV/0! | O18: =((J18/$K18)*100)-100 -> #DIV/0!
A19: =Sheet17!L1 -> 0 | B19: =MIN(Sheet17!B2:B5000) -> 0 | C19: =AVERAGE(Sheet17!B2:B5000) -> 0 | D19: =MAX(Sheet17!B2:B5000) -> 0 | E19: =Sheet17!G2 -> 0 | F19: =MIN(Sheet17!A2:A5000) -> 0 | G19: =MAX(Sheet17!A2:A5000) -> 0 | H19: =((G19-$Q$1)*($Q$3*B19^2))/1273 -> 0 | I19: =((G19-$Q$1)*($Q$3*C19^2))/1273 -> 0 | J19: =((G19-$Q$1)*($Q$3*D19^2))/1273 -> 0 | K19: =((G19-$Q$1)*($Q$3*E19^2))/1273 -> 0 | L19: =I19-K19 -> 0 | M19: =((H19/$K19)*100)-100 -> #DIV/0! | N19: =((I19/$K19)*100)-100 -> #DIV/0! | O19: =((J19/$K19)*100)-100 -> #DIV/0!
A20: =Sheet18!L1 -> 0 | B20: =MIN(Sheet18!B2:B5000) -> 0 | C20: =AVERAGE(Sheet18!B2:B5000) -> 0 | D20: =MAX(Sheet18!B2:B5000) -> 0 | E20: =Sheet18!G2 -> 0 | F20: =MIN(Sheet18!A2:A5000) -> 0 | G20: =MAX(Sheet18!A2:A5000) -> 0 | H20: =((G20-$Q$1)*($Q$3*B20^2))/1273 -> 0 | I20: =((G20-$Q$1)*($Q$3*C20^2))/1273 -> 0 | J20: =((G20-$Q$1)*($Q$3*D20^2))/1273 -> 0 | K20: =((G20-$Q$1)*($Q$3*E20^2))/1273 -> 0 | L20: =I20-K20 -> 0 | M20: =((H20/$K20)*100)-100 -> #DIV/0! | N20: =((I20/$K20)*100)-100 -> #DIV/0! | O20: =((J20/$K20)*100)-100 -> #DIV/0!
A21: =Sheet19!L1 -> 0 | B21: =MIN(Sheet19!B2:B5000) -> 0 | C21: =AVERAGE(Sheet19!B2:B5000) -> 0 | D21: =MAX(Sheet19!B2:B5000) -> 0 | E21: =Sheet19!G2 -> 0 | F21: =MIN(Sheet19!A2:A5000) -> 0 | G21: =MAX(Sheet19!A2:A5000) -> 0 | H21: =((G21-$Q$1)*($Q$3*B21^2))/1273 -> 0 | I21: =((G21-$Q$1)*($Q$3*C21^2))/1273 -> 0 | J21: =((G21-$Q$1)*($Q$3*D21^2))/1273 -> 0 | K21: =((G21-$Q$1)*($Q$3*E21^2))/1273 -> 0 | L21: =I21-K21 -> 0 | M21: =((H21/$K21)*100)-100 -> #DIV/0! | N21: =((I21/$K21)*100)-100 -> #DIV/0! | O21: =((J21/$K21)*100)-100 -> #DIV/0!
A22: =Sheet20!L1 -> 0 | B22: =MIN(Sheet20!B2:B5000) -> 0 | C22: =AVERAGE(Sheet20!B2:B5000) -> 0 | D22: =MAX(Sheet20!B2:B5000) -> 0 | E22: =Sheet20!G2 -> 0 | F22: =MIN(Sheet20!A2:A5000) -> 0 | G22: =MAX(Sheet20!A2:A5000) -> 0 | H22: =((G22-$Q$1)*($Q$3*B22^2))/1273 -> 0 | I22: =((G22-$Q$1)*($Q$3*C22^2))/1273 -> 0 | J22: =((G22-$Q$1)*($Q$3*D22^2))/1273 -> 0 | K22: =((G22-$Q$1)*($Q$3*E22^2))/1273 -> 0 | L22: =I22-K22 -> 0 | M22: =((H22/$K22)*100)-100 -> #DIV/0! | N22: =((I22/$K22)*100)-100 -> #DIV/0! | O22: =((J22/$K22)*100)-100 -> #DIV/0!
A23: =Sheet21!L1 -> 0 | B23: =MIN(Sheet21!B2:B5000) -> 0 | C23: =AVERAGE(Sheet21!B2:B5000) -> 0 | D23: =MAX(Sheet21!B2:B5000) -> 0 | E23: =Sheet21!G2 -> 0 | F23: =MIN(Sheet21!A2:A5000) -> 0 | G23: =MAX(Sheet21!A2:A5000) -> 0 | H23: =((G23-$Q$1)*($Q$3*B23^2))/1273 -> 0 | I23: =((G23-$Q$1)*($Q$3*C23^2))/1273 -> 0 | J23: =((G23-$Q$1)*($Q$3*D23^2))/1273 -> 0 | K23: =((G23-$Q$1)*($Q$3*E23^2))/1273 -> 0 | L23: =I23-K23 -> 0 | M23: =((H23/$K23)*100)-100 -> #DIV/0! | N23: =((I23/$K23)*100)-100 -> #DIV/0! | O23: =((J23/$K23)*100)-100 -> #DIV/0!
A24: =Sheet22!L1 -> 0 | B24: =MIN(Sheet22!B2:B5000) -> 0 | C24: =AVERAGE(Sheet22!B2:B5000) -> 0 | D24: =MAX(Sheet22!B2:B5000) -> 0 | E24: =Sheet22!G2 -> 0 | F24: =MIN(Sheet22!A2:A5000) -> 0 | G24: =MAX(Sheet22!A2:A5000) -> 0 | H24: =((G24-$Q$1)*($Q$3*B24^2))/1273 -> 0 | I24: =((G24-$Q$1)*($Q$3*C24^2))/1273 -> 0 | J24: =((G24-$Q$1)*($Q$3*D24^2))/1273 -> 0 | K24: =((G24-$Q$1)*($Q$3*E24^2))/1273 -> 0 | L24: =I24-K24 -> 0 | M24: =((H24/$K24)*100)-100 -> #DIV/0! | N24: =((I24/$K24)*100)-100 -> #DIV/0! | O24: =((J24/$K24)*100)-100 -> #DIV/0!
A25: =Sheet23!L1 -> 0 | B25: =MIN(Sheet23!B2:B5000) -> 0 | C25: =AVERAGE(Sheet23!B2:B5000) -> 0 | D25: =MAX(Sheet23!B2:B5000) -> 0 | E25: =Sheet23!G2 -> 0 | F25: =MIN(Sheet23!A2:A5000) -> 0 | G25: =MAX(Sheet23!A2:A5000) -> 0 | H25: =((G25-$Q$1)*($Q$3*B25^2))/1273 -> 0 | I25: =((G25-$Q$1)*($Q$3*C25^2))/1273 -> 0 | J25: =((G25-$Q$1)*($Q$3*D25^2))/1273 -> 0 | K25: =((G25-$Q$1)*($Q$3*E25^2))/1273 -> 0 | L25: =I25-K25 -> 0 | M25: =((H25/$K25)*100)-100 -> #DIV/0! | N25: =((I25/$K25)*100)-100 -> #DIV/0! | O25: =((J25/$K25)*100)-100 -> #DIV/0!
A26: =Sheet24!L1 -> 0 | B26: =MIN(Sheet24!B2:B5000) -> 0 | C26: =AVERAGE(Sheet24!B2:B5000) -> 0 | D26: =MAX(Sheet24!B2:B5000) -> 0 | E26: =Sheet24!G2 -> 0 | F26: =MIN(Sheet24!A2:A5000) -> 0 | G26: =MAX(Sheet24!A2:A5000) -> 0 | H26: =((G26-$Q$1)*($Q$3*B26^2))/1273 -> 0 | I26: =((G26-$Q$1)*($Q$3*C26^2))/1273 -> 0 | J26: =((G26-$Q$1)*($Q$3*D26^2))/1273 -> 0 | K26: =((G26-$Q$1)*($Q$3*E26^2))/1273 -> 0 | L26: =I26-K26 -> 0 | M26: =((H26/$K26)*100)-100 -> #DIV/0! | N26: =((I26/$K26)*100)-100 -> #DIV/0! | O26: =((J26/$K26)*100)-100 -> #DIV/0!
A27: =Sheet25!L1 -> 0 | B27: =MIN(Sheet25!B2:B5000) -> 0 | C27: =AVERAGE(Sheet25!B2:B5000) -> 0 | D27: =MAX(Sheet25!B2:B5000) -> 0 | E27: =Sheet25!G2 -> 0 | F27: =MIN(Sheet25!A2:A5000) -> 0 | G27: =MAX(Sheet25!A2:A5000) -> 0 | H27: =((G27-$Q$1)*($Q$3*B27^2))/1273 -> 0 | I27: =((G27-$Q$1)*($Q$3*C27^2))/1273 -> 0 | J27: =((G27-$Q$1)*($Q$3*D27^2))/1273 -> 0 | K27: =((G27-$Q$1)*($Q$3*E27^2))/1273 -> 0 | L27: =I27-K27 -> 0 | M27: =((H27/$K27)*100)-100 -> #DIV/0! | N27: =((I27/$K27)*100)-100 -> #DIV/0! | O27: =((J27/$K27)*100)-100 -> #DIV/0!
A28: =Sheet26!L1 -> 0 | B28: =MIN(Sheet26!B2:B5000) -> 0 | C28: =AVERAGE(Sheet26!B2:B5000) -> 0 | D28: =MAX(Sheet26!B2:B5000) -> 0 | E28: =Sheet26!G2 -> 0 | F28: =MIN(Sheet26!A2:A5000) -> 0 | G28: =MAX(Sheet26!A2:A5000) -> 0 | H28: =((G28-$Q$1)*($Q$3*B28^2))/1273 -> 0 | I28: =((G28-$Q$1)*($Q$3*C28^2))/1273 -> 0 | J28: =((G28-$Q$1)*($Q$3*D28^2))/1273 -> 0 | K28: =((G28-$Q$1)*($Q$3*E28^2))/1273 -> 0 | L28: =I28-K28 -> 0 | M28: =((H28/$K28)*100)-100 -> #DIV/0! | N28: =((I28/$K28)*100)-100 -> #DIV/0! | O28: =((J28/$K28)*100)-100 -> #DIV/0!
A29: =Sheet27!L1 -> 0 | B29: =MIN(Sheet27!B2:B5000) -> 0 | C29: =AVERAGE(Sheet27!B2:B5000) -> 0 | D29: =MAX(Sheet27!B2:B5000) -> 0 | E29: =Sheet27!G2 -> 0 | F29: =MIN(Sheet27!A2:A5000) -> 0 | G29: =MAX(Sheet27!A2:A5000) -> 0 | H29: =((G29-$Q$1)*($Q$3*B29^2))/1273 -> 0 | I29: =((G29-$Q$1)*($Q$3*C29^2))/1273 -> 0 | J29: =((G29-$Q$1)*($Q$3*D29^2))/1273 -> 0 | K29: =((G29-$Q$1)*($Q$3*E29^2))/1273 -> 0 | L29: =I29-K29 -> 0 | M29: =((H29/$K29)*100)-100 -> #DIV/0! | N29: =((I29/$K29)*100)-100 -> #DIV/0! | O29: =((J29/$K29)*100)-100 -> #DIV/0!
A30: =Sheet28!L1 -> 0 | B30: =MIN(Sheet28!B2:B5000) -> 0 | C30: =AVERAGE(Sheet28!B2:B5000) -> 0 | D30: =MAX(Sheet28!B2:B5000) -> 0 | E30: =Sheet28!G2 -> 0 | F30: =MIN(Sheet28!A2:A5000) -> 0 | G30: =MAX(Sheet28!A2:A5000) -> 0 | H30: =((G30-$Q$1)*($Q$3*B30^2))/1273 -> 0 | I30: =((G30-$Q$1)*($Q$3*C30^2))/1273 -> 0 | J30: =((G30-$Q$1)*($Q$3*D30^2))/1273 -> 0 | K30: =((G30-$Q$1)*($Q$3*E30^2))/1273 -> 0 | L30: =I30-K30 -> 0 | M30: =((H30/$K30)*100)-100 -> #DIV/0! | N30: =((I30/$K30)*100)-100 -> #DIV/0! | O30: =((J30/$K30)*100)-100 -> #DIV/0!
A31: =Sheet29!L1 -> 0 | B31: =MIN(Sheet29!B2:B5000) -> 0 | C31: =AVERAGE(Sheet29!B2:B5000) -> 0 | D31: =MAX(Sheet29!B2:B5000) -> 0 | E31: =Sheet29!G2 -> 0 | F31: =MIN(Sheet29!A2:A5000) -> 0 | G31: =MAX(Sheet29!A2:A5000) -> 0 | H31: =((G31-$Q$1)*($Q$3*B31^2))/1273 -> 0 | I31: =((G31-$Q$1)*($Q$3*C31^2))/1273 -> 0 | J31: =((G31-$Q$1)*($Q$3*D31^2))/1273 -> 0 | K31: =((G31-$Q$1)*($Q$3*E31^2))/1273 -> 0 | L31: =I31-K31 -> 0 | M31: =((H31/$K31)*100)-100 -> #DIV/0! | N31: =((I31/$K31)*100)-100 -> #DIV/0! | O31: =((J31/$K31)*100)-100 -> #DIV/0!
A32: =Sheet30!L1 -> 0 | B32: =MIN(Sheet30!B2:B5000) -> 0 | C32: =AVERAGE(Sheet30!B2:B5000) -> 0 | D32: =MAX(Sheet30!B2:B5000) -> 0 | E32: =Sheet30!G2 -> 0 | F32: =MIN(Sheet30!A2:A5000) -> 0 | G32: =MAX(Sheet30!A2:A5000) -> 0 | H32: =((G32-$Q$1)*($Q$3*B32^2))/1273 -> 0 | I32: =((G32-$Q$1)*($Q$3*C32^2))/1273 -> 0 | J32: =((G32-$Q$1)*($Q$3*D32^2))/1273 -> 0 | K32: =((G32-$Q$1)*($Q$3*E32^2))/1273 -> 0 | L32: =I32-K32 -> 0 | M32: =((H32/$K32)*100)-100 -> #DIV/0! | N32: =((I32/$K32)*100)-100 -> #DIV/0! | O32: =((J32/$K32)*100)-100 -> #DIV/0!
A33: =Sheet31!L1 -> 0 | B33: =MIN(Sheet31!B2:B5000) -> 0 | C33: =AVERAGE(Sheet31!B2:B5000) -> 0 | D33: =MAX(Sheet31!B2:B5000) -> 0 | E33: =Sheet31!G2 -> 0 | F33: =MIN(Sheet31!A2:A5000) -> 0 | G33: =MAX(Sheet31!A2:A5000) -> 0 | H33: =((G33-$Q$1)*($Q$3*B33^2))/1273 -> 0 | I33: =((G33-$Q$1)*($Q$3*C33^2))/1273 -> 0 | J33: =((G33-$Q$1)*($Q$3*D33^2))/1273 -> 0 | K33: =((G33-$Q$1)*($Q$3*E33^2))/1273 -> 0 | L33: =I33-K33 -> 0 | M33: =((H33/$K33)*100)-100 -> #DIV/0! | N33: =((I33/$K33)*100)-100 -> #DIV/0! | O33: =((J33/$K33)*100)-100 -> #DIV/0!
A34: =Sheet32!L1 -> 0 | B34: =MIN(Sheet32!B2:B5000) -> 0 | C34: =AVERAGE(Sheet32!B2:B5000) -> 0 | D34: =MAX(Sheet32!B2:B5000) -> 0 | E34: =Sheet32!G2 -> 0 | F34: =MIN(Sheet32!A2:A5000) -> 0 | G34: =MAX(Sheet32!A2:A5000) -> 0 | H34: =((G34-$Q$1)*($Q$3*B34^2))/1273 -> 0 | I34: =((G34-$Q$1)*($Q$3*C34^2))/1273 -> 0 | J34: =((G34-$Q$1)*($Q$3*D34^2))/1273 -> 0 | K34: =((G34-$Q$1)*($Q$3*E34^2))/1273 -> 0 | L34: =I34-K34 -> 0 | M34: =((H34/$K34)*100)-100 -> #DIV/0! | N34: =((I34/$K34)*100)-100 -> #DIV/0! | O34: =((J34/$K34)*100)-100 -> #DIV/0!
A35: =Sheet33!L1 -> 0 | B35: =MIN(Sheet33!B2:B5000) -> 0 | C35: =AVERAGE(Sheet33!B2:B5000) -> 0 | D35: =MAX(Sheet33!B2:B5000) -> 0 | E35: =Sheet33!G2 -> 0 | F35: =MIN(Sheet33!A2:A5000) -> 0 | G35: =MAX(Sheet33!A2:A5000) -> 0 | H35: =((G35-$Q$1)*($Q$3*B35^2))/1273 -> 0 | I35: =((G35-$Q$1)*($Q$3*C35^2))/1273 -> 0 | J35: =((G35-$Q$1)*($Q$3*D35^2))/1273 -> 0 | K35: =((G35-$Q$1)*($Q$3*E35^2))/1273 -> 0 | L35: =I35-K35 -> 0 | M35: =((H35/$K35)*100)-100 -> #DIV/0! | N35: =((I35/$K35)*100)-100 -> #DIV/0! | O35: =((J35/$K35)*100)-100 -> #DIV/0!
A36: =Sheet34!L1 -> 0 | B36: =MIN(Sheet34!B2:B5000) -> 0 | C36: =AVERAGE(Sheet34!B2:B5000) -> 0 | D36: =MAX(Sheet34!B2:B5000) -> 0 | E36: =Sheet34!G2 -> 0 | F36: =MIN(Sheet34!A2:A5000) -> 0 | G36: =MAX(Sheet34!A2:A5000) -> 0 | H36: =((G36-$Q$1)*($Q$3*B36^2))/1273 -> 0 | I36: =((G36-$Q$1)*($Q$3*C36^2))/1273 -> 0 | J36: =((G36-$Q$1)*($Q$3*D36^2))/1273 -> 0 | K36: =((G36-$Q$1)*($Q$3*E36^2))/1273 -> 0 | L36: =I36-K36 -> 0 | M36: =((H36/$K36)*100)-100 -> #DIV/0! | N36: =((I36/$K36)*100)-100 -> #DIV/0! | O36: =((J36/$K36)*100)-100 -> #DIV/0!
A37: =Sheet35!L1 -> 0 | B37: =MIN(Sheet35!B2:B5000) -> 0 | C37: =AVERAGE(Sheet35!B2:B5000) -> 0 | D37: =MAX(Sheet35!B2:B5000) -> 0 | E37: =Sheet35!G2 -> 0 | F37: =MIN(Sheet35!A2:A5000) -> 0 | G37: =MAX(Sheet35!A2:A5000) -> 0 | H37: =((G37-$Q$1)*($Q$3*B37^2))/1273 -> 0 | I37: =((G37-$Q$1)*($Q$3*C37^2))/1273 -> 0 | J37: =((G37-$Q$1)*($Q$3*D37^2))/1273 -> 0 | K37: =((G37-$Q$1)*($Q$3*E37^2))/1273 -> 0 | L37: =I37-K37 -> 0 | M37: =((H37/$K37)*100)-100 -> #DIV/0! | N37: =((I37/$K37)*100)-100 -> #DIV/0! | O37: =((J37/$K37)*100)-100 -> #DIV/0!
A38: =Sheet36!L1 -> 0 | B38: =MIN(Sheet36!B2:B5000) -> 0 | C38: =AVERAGE(Sheet36!B2:B5000) -> 0 | D38: =MAX(Sheet36!B2:B5000) -> 0 | E38: =Sheet36!G2 -> 0 | F38: =MIN(Sheet36!A2:A5000) -> 0 | G38: =MAX(Sheet36!A2:A5000) -> 0 | H38: =((G38-$Q$1)*($Q$3*B38^2))/1273 -> 0 | I38: =((G38-$Q$1)*($Q$3*C38^2))/1273 -> 0 | J38: =((G38-$Q$1)*($Q$3*D38^2))/1273 -> 0 | K38: =((G38-$Q$1)*($Q$3*E38^2))/1273 -> 0 | L38: =I38-K38 -> 0 | M38: =((H38/$K38)*100)-100 -> #DIV/0! | N38: =((I38/$K38)*100)-100 -> #DIV/0! | O38: =((J38/$K38)*100)-100 -> #DIV/0!
A39: =Sheet37!L1 -> 0 | B39: =MIN(Sheet37!B2:B5000) -> 0 | C39: =AVERAGE(Sheet37!B2:B5000) -> 0 | D39: =MAX(Sheet37!B2:B5000) -> 0 | E39: =Sheet37!G2 -> 0 | F39: =MIN(Sheet37!A2:A5000) -> 0 | G39: =MAX(Sheet37!A2:A5000) -> 0 | H39: =((G39-$Q$1)*($Q$3*B39^2))/1273 -> 0 | I39: =((G39-$Q$1)*($Q$3*C39^2))/1273 -> 0 | J39: =((G39-$Q$1)*($Q$3*D39^2))/1273 -> 0 | K39: =((G39-$Q$1)*($Q$3*E39^2))/1273 -> 0 | L39: =I39-K39 -> 0 | M39: =((H39/$K39)*100)-100 -> #DIV/0! | N39: =((I39/$K39)*100)-100 -> #DIV/0! | O39: =((J39/$K39)*100)-100 -> #DIV/0!
A40: =Sheet38!L1 -> 0 | B40: =MIN(Sheet38!B2:B5000) -> 0 | C40: =AVERAGE(Sheet38!B2:B5000) -> 0 | D40: =MAX(Sheet38!B2:B5000) -> 0 | E40: =Sheet38!G2 -> 0 | F40: =MIN(Sheet38!A2:A5000) -> 0 | G40: =MAX(Sheet38!A2:A5000) -> 0 | H40: =((G40-$Q$1)*($Q$3*B40^2))/1273 -> 0 | I40: =((G40-$Q$1)*($Q$3*C40^2))/1273 -> 0 | J40: =((G40-$Q$1)*($Q$3*D40^2))/1273 -> 0 | K40: =((G40-$Q$1)*($Q$3*E40^2))/1273 -> 0 | L40: =I40-K40 -> 0 | M40: =((H40/$K40)*100)-100 -> #DIV/0! | N40: =((I40/$K40)*100)-100 -> #DIV/0! | O40: =((J40/$K40)*100)-100 -> #DIV/0!
...

Sheet Information
A1: Client:
A2: Mine:
A3: Block:
A4: Hole Diameter:
A5: Final Stemming:
A6: Average In-hole Density:
A7: Rig Operator:
A8: Date of Calipering:

Sheet Sheet1
A1: Depth | B1: x | C1: Actual+ | D1: Actual- | E1: Planned+ | F1: Planned- | G1: Planned diameter | H1: Actual deviation X | J1: Hole Number | M1: =Information!C2 -> 0 | N1: =Information!C3 -> 0
A2: 0 | B2: 0 | C2: =B2/2 -> 0 | D2: =(B2-(B2*2))/2 -> 0 | E2: =G2/2 -> 0 | F2: =(G2-(G2*2))/2 -> 0 | G2: =Information!C$4 -> 0 | H2: =B2-G2 -> 0 | J2: MAX | K2: =MAX(B2:B2500) -> 0
J3: MIN | K3: =MIN(B2:B2500) -> 0
J4: AVE | K4: =AVERAGE(B2:B2500) -> 0

Sheet Sheet2
A1: Depth | B1: x | C1: Actual+ | D1: Actual- | E1: Planned+ | F1: Planned- | G1: Planned diameter | H1: Actual deviation X | J1: Hole Number | M1: =Information!C2 -> 0 | N1: =Information!C3 -> 0
A2: 0 | B2: 0 | C2: =B2/2 -> 0 | D2: =(B2-(B2*2))/2 -> 0 | E2: =G2/2 -> 0 | F2: =(G2-(G2*2))/2 -> 0 | G2: =Information!C$4 -> 0 | H2: =B2-G2 -> 0 | J2: MAX | K2: =MAX(B2:B2500) -> 0
J3: MIN | K3: =MIN(B2:B2500) -> 0
J4: AVE | K4: =AVERAGE(B2:B2500) -> 0

Sheet Sheet3
A1: Depth | B1: x | C1: Actual+ | D1: Actual- | E1: Planned+ | F1: Planned- | G1: Planned diameter | H1: Actual deviation X | J1: Hole Number | M1: =Information!C2 -> 0 | N1: =Information!C3 -> 0
A2: 0 | B2: 0 | C2: =B2/2 -> 0 | D2: =(B2-(B2*2))/2 -> 0 | E2: =G2/2 -> 0 | F2: =(G2-(G2*2))/2 -> 0 | G2: =Information!C$4 -> 0 | H2: =B2-G2 -> 0 | J2: MAX | K2: =MAX(B2:B2500) -> 0
J3: MIN | K3: =MIN(B2:B2500) -> 0
J4: AVE | K4: =AVERAGE(B2:B2500) -> 0

Sheet Sheet4
A1: Depth | B1: x | C1: Actual+ | D1: Actual- | E1: Planned+ | F1: Planned- | G1: Planned diameter | H1: Actual deviation X | J1: Hole Number | M1: =Information!C2 -> 0 | N1: =Information!C3 -> 0
A2: 0 | B2: 0 | C2: =B2/2 -> 0 | D2: =(B2-(B2*2))/2 -> 0 | E2: =G2/2 -> 0 | F2: =(G2-(G2*2))/2 -> 0 | G2: =Information!C$4 -> 0 | H2: =B2-G2 -> 0 | J2: MAX | K2: =MAX(B2:B2500) -> 0
J3: MIN | K3: =MIN(B2:B2500) -> 0
J4: AVE | K4: =AVERAGE(B2:B2500) -> 0

Sheet Sheet5
A1: Depth | B1: x | C1: Actual+ | D1: Actual- | E1: Planned+ | F1: Planned- | G1: Planned diameter | H1: Actual deviation X | J1: Hole Number | M1: =Information!C2 -> 0 | N1: =Information!C3 -> 0
A2: 0 | B2: 0 | C2: =B2/2 -> 0 | D2: =(B2-(B2*2))/2 -> 0 | E2: =G2/2 -> 0 | F2: =(G2-(G2*2))/2 -> 0 | G2: =Information!C$4 -> 0 | H2: =B2-G2 -> 0 | J2: MAX | K2: =MAX(B2:B2500) -> 0
J3: MIN | K3: =MIN(B2:B2500) -> 0
J4: AVE | K4: =AVERAGE(B2:B2500) -> 0

Sheet Sheet6
A1: Depth | B1: x | C1: Actual+ | D1: Actual- | E1: Planned+ | F1: Planned- | G1: Planned diameter | H1: Actual deviation X | J1: Hole Number | M1: =Information!C2 -> 0 | N1: =Information!C3 -> 0
A2: 0 | B2: 0 | C2: =B2/2 -> 0 | D2: =(B2-(B2*2))/2 -> 0 | E2: =G2/2 -> 0 | F2: =(G2-(G2*2))/2 -> 0 | G2: =Information!C$4 -> 0 | H2: =B2-G2 -> 0 | J2: MAX | K2: =MAX(B2:B2500) -> 0
J3: MIN | K3: =MIN(B2:B2500) -> 0
J4: AVE | K4: =AVERAGE(B2:B2500) -> 0

Sheet Sheet7
A1: Depth | B1: x | C1: Actual+ | D1: Actual- | E1: Planned+ | F1: Planned- | G1: Planned diameter | H1: Actual deviation X | J1: Hole Number | M1: =Information!C2 -> 0 | N1: =Information!C3 -> 0
A2: 0 | B2: 0 | C2: =B2/2 -> 0 | D2: =(B2-(B2*2))/2 -> 0 | E2: =G2/2 -> 0 | F2: =(G2-(G2*2))/2 -> 0 | G2: =Information!C$4 -> 0 | H2: =B2-G2 -> 0 | J2: MAX | K2: =MAX(B2:B2500) -> 0
J3: MIN | K3: =MIN(B2:B2500) -> 0
J4: AVE | K4: =AVERAGE(B2:B2500) -> 0

Sheet Sheet8
A1: Depth | B1: x | C1: Actual+ | D1: Actual- | E1: Planned+ | F1: Planned- | G1: Planned diameter | H1: Actual deviation X | J1: Hole Number | M1: =Information!C2 -> 0 | N1: =Information!C3 -> 0
A2: 0 | B2: 0 | C2: =B2/2 -> 0 | D2: =(B2-(B2*2))/2 -> 0 | E2: =G2/2 -> 0 | F2: =(G2-(G2*2))/2 -> 0 | G2: =Information!C$4 -> 0 | H2: =B2-G2 -> 0 | J2: MAX | K2: =MAX(B2:B2500) -> 0
J3: MIN | K3: =MIN(B2:B2500) -> 0
J4: AVE | K4: =AVERAGE(B2:B2500) -> 0

Sheet Sheet9
A1: Depth | B1: x | C1: Actual+ | D1: Actual- | E1: Planned+ | F1: Planned- | G1: Planned diameter | H1: Actual deviation X | J1: Hole Number | M1: =Information!C2 -> 0 | N1: =Information!C3 -> 0
A2: 0 | B2: 0 | C2: =B2/2 -> 0 | D2: =(B2-(B2*2))/2 -> 0 | E2: =G2/2 -> 0 | F2: =(G2-(G2*2))/2 -> 0 | G2: =Information!C$4 -> 0 | H2: =B2-G2 -> 0 | J2: MAX | K2: =MAX(B2:B2500) -> 0
J3: MIN | K3: =MIN(B2:B2500) -> 0
J4: AVE | K4: =AVERAGE(B2:B2500) -> 0

Sheet Sheet10
A1: Depth | B1: x | C1: Actual+ | D1: Actual- | E1: Planned+ | F1: Planned- | G1: Planned diameter | H1: Actual deviation X | J1: Hole Number | M1: =Information!C2 -> 0 | N1: =Information!C3 -> 0
A2: 0 | B2: 0 | C2: =B2/2 -> 0 | D2: =(B2-(B2*2))/2 -> 0 | E2: =G2/2 -> 0 | F2: =(G2-(G2*2))/2 -> 0 | G2: =Information!C$4 -> 0 | H2: =B2-G2 -> 0 | J2: MAX | K2: =MAX(B2:B2500) -> 0
J3: MIN | K3: =MIN(B2:B2500) -> 0
J4: AVE | K4: =AVERAGE(B2:B2500) -> 0

Sheet Sheet11
A1: Depth | B1: x | C1: Actual+ | D1: Actual- | E1: Planned+ | F1: Planned- | G1: Planned diameter | H1: Actual deviation X | J1: Hole Number | M1: =Information!C2 -> 0 | N1: =Information!C3 -> 0
A2: 0 | B2: 0 | C2: =B2/2 -> 0 | D2: =(B2-(B2*2))/2 -> 0 | E2: =G2/2 -> 0 | F2: =(G2-(G2*2))/2 -> 0 | G2: =Information!C$4 -> 0 | H2: =B2-G2 -> 0 | J2: MAX | K2: =MAX(B2:B2500) -> 0
J3: MIN | K3: =MIN(B2:B2500) -> 0
J4: AVE | K4: =AVERAGE(B2:B2500) -> 0

Sheet Sheet12
A1: Depth | B1: x | C1: Actual+ | D1: Actual- | E1: Planned+ | F1: Planned- | G1: Planned diameter | H1: Actual deviation X | J1: Hole Number | M1: =Information!C2 -> 0 | N1: =Information!C3 -> 0
A2: 0 | B2: 0 | C2: =B2/2 -> 0 | D2: =(B2-(B2*2))/2 -> 0 | E2: =G2/2 -> 0 | F2: =(G2-(G2*2))/2 -> 0 | G2: =Information!C$4 -> 0 | H2: =B2-G2 -> 0 | J2: MAX | K2: =MAX(B2:B2500) -> 0
J3: MIN | K3: =MIN(B2:B2500) -> 0
J4: AVE | K4: =AVERAGE(B2:B2500) -> 0

Sheet Sheet13
A1: Depth | B1: x | C1: Actual+ | D1: Actual- | E1: Planned+ | F1: Planned- | G1: Planned diameter | H1: Actual deviation X | J1: Hole Number | M1: =Information!C2 -> 0 | N1: =Information!C3 -> 0
A2: 0 | B2: 0 | C2: =B2/2 -> 0 | D2: =(B2-(B2*2))/2 -> 0 | E2: =G2/2 -> 0 | F2: =(G2-(G2*2))/2 -> 0 | G2: =Information!C$4 -> 0 | H2: =B2-G2 -> 0 | J2: MAX | K2: =MAX(B2:B2500) -> 0
J3: MIN | K3: =MIN(B2:B2500) -> 0
J4: AVE | K4: =AVERAGE(B2:B2500) -> 0

Sheet Sheet14
A1: Depth | B1: x | C1: Actual+ | D1: Actual- | E1: Planned+ | F1: Planned- | G1: Planned diameter | H1: Actual deviation X | J1: Hole Number | M1: =Information!C2 -> 0 | N1: =Information!C3 -> 0
A2: 0 | B2: 0 | C2: =B2/2 -> 0 | D2: =(B2-(B2*2))/2 -> 0 | E2: =G2/2 -> 0 | F2: =(G2-(G2*2))/2 -> 0 | G2: =Information!C$4 -> 0 | H2: =B2-G2 -> 0 | J2: MAX | K2: =MAX(B2:B2500) -> 0
J3: MIN | K3: =MIN(B2:B2500) -> 0
J4: AVE | K4: =AVERAGE(B2:B2500) -> 0

Sheet Sheet15
A1: Depth | B1: x | C1: Actual+ | D1: Actual- | E1: Planned+ | F1: Planned- | G1: Planned diameter | H1: Actual deviation X | J1: Hole Number | M1: =Information!C2 -> 0 | N1: =Information!C3 -> 0
A2: 0 | B2: 0 | C2: =B2/2 -> 0 | D2: =(B2-(B2*2))/2 -> 0 | E2: =G2/2 -> 0 | F2: =(G2-(G2*2))/2 -> 0 | G2: =Information!C$4 -> 0 | H2: =B2-G2 -> 0 | J2: MAX | K2: =MAX(B2:B2500) -> 0
J3: MIN | K3: =MIN(B2:B2500) -> 0
J4: AVE | K4: =AVERAGE(B2:B2500) -> 0

Sheet Sheet16
A1: Depth | B1: x | C1: Actual+ | D1: Actual- | E1: Planned+ | F1: Planned- | G1: Planned diameter | H1: Actual deviation X | J1: Hole Number | M1: =Information!C2 -> 0 | N1: =Information!C3 -> 0
A2: 0 | B2: 0 | C2: =B2/2 -> 0 | D2: =(B2-(B2*2))/2 -> 0 | E2: =G2/2 -> 0 | F2: =(G2-(G2*2))/2 -> 0 | G2: =Information!C$4 -> 0 | H2: =B2-G2 -> 0 | J2: MAX | K2: =MAX(B2:B2500) -> 0
J3: MIN | K3: =MIN(B2:B2500) -> 0
J4: AVE | K4: =AVERAGE(B2:B2500) -> 0

Sheet Sheet17
A1: Depth | B1: x | C1: Actual+ | D1: Actual- | E1: Planned+ | F1: Planned- | G1: Planned diameter | H1: Actual deviation X | J1: Hole Number | M1: =Information!C2 -> 0 | N1: =Information!C3 -> 0
A2: 0 | B2: 0 | C2: =B2/2 -> 0 | D2: =(B2-(B2*2))/2 -> 0 | E2: =G2/2 -> 0 | F2: =(G2-(G2*2))/2 -> 0 | G2: =Information!C$4 -> 0 | H2: =B2-G2 -> 0 | J2: MAX | K2: =MAX(B2:B2500) -> 0
J3: MIN | K3: =MIN(B2:B2500) -> 0
J4: AVE | K4: =AVERAGE(B2:B2500) -> 0

Sheet Sheet18
A1: Depth | B1: x | C1: Actual+ | D1: Actual- | E1: Planned+ | F1: Planned- | G1: Planned diameter | H1: Actual deviation X | J1: Hole Number | M1: =Information!C2 -> 0 | N1: =Information!C3 -> 0
A2: 0 | B2: 0 | C2: =B2/2 -> 0 | D2: =(B2-(B2*2))/2 -> 0 | E2: =G2/2 -> 0 | F2: =(G2-(G2*2))/2 -> 0 | G2: =Information!C$4 -> 0 | H2: =B2-G2 -> 0 | J2: MAX | K2: =MAX(B2:B2500) -> 0
J3: MIN | K3: =MIN(B2:B2500) -> 0
J4: AVE | K4: =AVERAGE(B2:B2500) -> 0

Sheet Sheet19
A1: Depth | B1: x | C1: Actual+ | D1: Actual- | E1: Planned+ | F1: Planned- | G1: Planned diameter | H1: Actual deviation X | J1: Hole Number | M1: =Information!C2 -> 0 | N1: =Information!C3 -> 0
A2: 0 | B2: 0 | C2: =B2/2 -> 0 | D2: =(B2-(B2*2))/2 -> 0 | E2: =G2/2 -> 0 | F2: =(G2-(G2*2))/2 -> 0 | G2: =Information!C$4 -> 0 | H2: =B2-G2 -> 0 | J2: MAX | K2: =MAX(B2:B2500) -> 0
J3: MIN | K3: =MIN(B2:B2500) -> 0
J4: AVE | K4: =AVERAGE(B2:B2500) -> 0

Sheet Sheet20
A1: Depth | B1: x | C1: Actual+ | D1: Actual- | E1: Planned+ | F1: Planned- | G1: Planned diameter | H1: Actual deviation X | J1: Hole Number | M1: =Information!C2 -> 0 | N1: =Information!C3 -> 0
A2: 0 | B2: 0 | C2: =B2/2 -> 0 | D2: =(B2-(B2*2))/2 -> 0 | E2: =G2/2 -> 0 | F2: =(G2-(G2*2))/2 -> 0 | G2: =Information!C$4 -> 0 | H2: =B2-G2 -> 0 | J2: MAX | K2: =MAX(B2:B2500) -> 0
J3: MIN | K3: =MIN(B2:B2500) -> 0
J4: AVE | K4: =AVERAGE(B2:B2500) -> 0

Sheet Sheet21
A1: Depth | B1: x | C1: Actual+ | D1: Actual- | E1: Planned+ | F1: Planned- | G1: Planned diameter | H1: Actual deviation X | J1: Hole Number | M1: =Information!C2 -> 0 | N1: =Information!C3 -> 0
A2: 0 | B2: 0 | C2: =B2/2 -> 0 | D2: =(B2-(B2*2))/2 -> 0 | E2: =G2/2 -> 0 | F2: =(G2-(G2*2))/2 -> 0 | G2: =Information!C$4 -> 0 | H2: =B2-G2 -> 0 | J2: MAX | K2: =MAX(B2:B2500) -> 0
J3: MIN | K3: =MIN(B2:B2500) -> 0
J4: AVE | K4: =AVERAGE(B2:B2500) -> 0

Sheet Sheet22
A1: Depth | B1: x | C1: Actual+ | D1: Actual- | E1: Planned+ | F1: Planned- | G1: Planned diameter | H1: Actual deviation X | J1: Hole Number | M1: =Information!C2 -> 0 | N1: =Information!C3 -> 0
A2: 0 | B2: 0 | C2: =B2/2 -> 0 | D2: =(B2-(B2*2))/2 -> 0 | E2: =G2/2 -> 0 | F2: =(G2-(G2*2))/2 -> 0 | G2: =Information!C$4 -> 0 | H2: =B2-G2 -> 0 | J2: MAX | K2: =MAX(B2:B2500) -> 0
J3: MIN | K3: =MIN(B2:B2500) -> 0
J4: AVE | K4: =AVERAGE(B2:B2500) -> 0

Sheet Sheet23
A1: Depth | B1: x | C1: Actual+ | D1: Actual- | E1: Planned+ | F1: Planned- | G1: Planned diameter | H1: Actual deviation X | J1: Hole Number | M1: =Information!C2 -> 0 | N1: =Information!C3 -> 0
A2: 0 | B2: 0 | C2: =B2/2 -> 0 | D2: =(B2-(B2*2))/2 -> 0 | E2: =G2/2 -> 0 | F2: =(G2-(G2*2))/2 -> 0 | G2: =Information!C$4 -> 0 | H2: =B2-G2 -> 0 | J2: MAX | K2: =MAX(B2:B2500) -> 0
J3: MIN | K3: =MIN(B2:B2500) -> 0
J4: AVE | K4: =AVERAGE(B2:B2500) -> 0

Sheet Sheet24
A1: Depth | B1: x | C1: Actual+ | D1: Actual- | E1: Planned+ | F1: Planned- | G1: Planned diameter | H1: Actual deviation X | J1: Hole Number | M1: =Information!C2 -> 0 | N1: =Information!C3 -> 0
A2: 0 | B2: 0 | C2: =B2/2 -> 0 | D2: =(B2-(B2*2))/2 -> 0 | E2: =G2/2 -> 0 | F2: =(G2-(G2*2))/2 -> 0 | G2: =Information!C$4 -> 0 | H2: =B2-G2 -> 0 | J2: MAX | K2: =MAX(B2:B2500) -> 0
J3: MIN | K3: =MIN(B2:B2500) -> 0
J4: AVE | K4: =AVERAGE(B2:B2500) -> 0

Sheet Sheet25
A1: Depth | B1: x | C1: Actual+ | D1: Actual- | E1: Planned+ | F1: Planned- | G1: Planned diameter | H1: Actual deviation X | J1: Hole Number | M1: =Information!C2 -> 0 | N1: =Information!C3 -> 0
A2: 0 | B2: 0 | C2: =B2/2 -> 0 | D2: =(B2-(B2*2))/2 -> 0 | E2: =G2/2 -> 0 | F2: =(G2-(G2*2))/2 -> 0 | G2: =Information!C$4 -> 0 | H2: =B2-G2 -> 0 | J2: MAX | K2: =MAX(B2:B2500) -> 0
J3: MIN | K3: =MIN(B2:B2500) -> 0
J4: AVE | K4: =AVERAGE(B2:B2500) -> 0

Sheet Sheet26
A1: Depth | B1: x | C1: Actual+ | D1: Actual- | E1: Planned+ | F1: Planned- | G1: Planned diameter | H1: Actual deviation X | J1: Hole Number | M1: =Information!C2 -> 0 | N1: =Information!C3 -> 0
A2: 0 | B2: 0 | C2: =B2/2 -> 0 | D2: =(B2-(B2*2))/2 -> 0 | E2: =G2/2 -> 0 | F2: =(G2-(G2*2))/2 -> 0 | G2: =Information!C$4 -> 0 | H2: =B2-G2 -> 0 | J2: MAX | K2: =MAX(B2:B2500) -> 0
J3: MIN | K3: =MIN(B2:B2500) -> 0
J4: AVE | K4: =AVERAGE(B2:B2500) -> 0

Sheet Sheet27
A1: Depth | B1: x | C1: Actual+ | D1: Actual- | E1: Planned+ | F1: Planned- | G1: Planned diameter | H1: Actual deviation X | J1: Hole Number | M1: =Information!C2 -> 0 | N1: =Information!C3 -> 0
A2: 0 | B2: 0 | C2: =B2/2 -> 0 | D2: =(B2-(B2*2))/2 -> 0 | E2: =G2/2 -> 0 | F2: =(G2-(G2*2))/2 -> 0 | G2: =Information!C$4 -> 0 | H2: =B2-G2 -> 0 | J2: MAX | K2: =MAX(B2:B2500) -> 0
J3: MIN | K3: =MIN(B2:B2500) -> 0
J4: AVE | K4: =AVERAGE(B2:B2500) -> 0

Sheet Sheet28
A1: Depth | B1: x | C1: Actual+ | D1: Actual- | E1: Planned+ | F1: Planned- | G1: Planned diameter | H1: Actual deviation X | J1: Hole Number | M1: =Information!C2 -> 0 | N1: =Information!C3 -> 0
A2: 0 | B2: 0 | C2: =B2/2 -> 0 | D2: =(B2-(B2*2))/2 -> 0 | E2: =G2/2 -> 0 | F2: =(G2-(G2*2))/2 -> 0 | G2: =Information!C$4 -> 0 | H2: =B2-G2 -> 0 | J2: MAX | K2: =MAX(B2:B2500) -> 0
J3: MIN | K3: =MIN(B2:B2500) -> 0
J4: AVE | K4: =AVERAGE(B2:B2500) -> 0

Sheet Sheet29
A1: Depth | B1: x | C1: Actual+ | D1: Actual- | E1: Planned+ | F1: Planned- | G1: Planned diameter | H1: Actual deviation X | J1: Hole Number | M1: =Information!C2 -> 0 | N1: =Information!C3 -> 0
A2: 0 | B2: 0 | C2: =B2/2 -> 0 | D2: =(B2-(B2*2))/2 -> 0 | E2: =G2/2 -> 0 | F2: =(G2-(G2*2))/2 -> 0 | G2: =Information!C$4 -> 0 | H2: =B2-G2 -> 0 | J2: MAX | K2: =MAX(B2:B2500) -> 0
J3: MIN | K3: =MIN(B2:B2500) -> 0
J4: AVE | K4: =AVERAGE(B2:B2500) -> 0

Sheet Sheet30
A1: Depth | B1: x | C1: Actual+ | D1: Actual- | E1: Planned+ | F1: Planned- | G1: Planned diameter | H1: Actual deviation X | J1: Hole Number | M1: =Information!C2 -> 0 | N1: =Information!C3 -> 0
A2: 0 | B2: 0 | C2: =B2/2 -> 0 | D2: =(B2-(B2*2))/2 -> 0 | E2: =G2/2 -> 0 | F2: =(G2-(G2*2))/2 -> 0 | G2: =Information!C$4 -> 0 | H2: =B2-G2 -> 0 | J2: MAX | K2: =MAX(B2:B2500) -> 0
J3: MIN | K3: =MIN(B2:B2500) -> 0
J4: AVE | K4: =AVERAGE(B2:B2500) -> 0

Sheet Sheet31
A1: Depth | B1: x | C1: Actual+ | D1: Actual- | E1: Planned+ | F1: Planned- | G1: Planned diameter | H1: Actual deviation X | J1: Hole Number | M1: =Information!C2 -> 0 | N1: =Information!C3 -> 0
A2: 0 | B2: 0 | C2: =B2/2 -> 0 | D2: =(B2-(B2*2))/2 -> 0 | E2: =G2/2 -> 0 | F2: =(G2-(G2*2))/2 -> 0 | G2: =Information!C$4 -> 0 | H2: =B2-G2 -> 0 | J2: MAX | K2: =MAX(B2:B2500) -> 0
J3: MIN | K3: =MIN(B2:B2500) -> 0
J4: AVE | K4: =AVERAGE(B2:B2500) -> 0

Sheet Sheet32
A1: Depth | B1: x | C1: Actual+ | D1: Actual- | E1: Planned+ | F1: Planned- | G1: Planned diameter | H1: Actual deviation X | J1: Hole Number | M1: =Information!C2 -> 0 | N1: =Information!C3 -> 0
A2: 0 | B2: 0 | C2: =B2/2 -> 0 | D2: =(B2-(B2*2))/2 -> 0 | E2: =G2/2 -> 0 | F2: =(G2-(G2*2))/2 -> 0 | G2: =Information!C$4 -> 0 | H2: =B2-G2 -> 0 | J2: MAX | K2: =MAX(B2:B2500) -> 0
J3: MIN | K3: =MIN(B2:B2500) -> 0
J4: AVE | K4: =AVERAGE(B2:B2500) -> 0

Sheet Sheet33
A1: Depth | B1: x | C1: Actual+ | D1: Actual- | E1: Planned+ | F1: Planned- | G1: Planned diameter | H1: Actual deviation X | J1: Hole Number | M1: =Information!C2 -> 0 | N1: =Information!C3 -> 0
A2: 0 | B2: 0 | C2: =B2/2 -> 0 | D2: =(B2-(B2*2))/2 -> 0 | E2: =G2/2 -> 0 | F2: =(G2-(G2*2))/2 -> 0 | G2: =Information!C$4 -> 0 | H2: =B2-G2 -> 0 | J2: MAX | K2: =MAX(B2:B2500) -> 0
J3: MIN | K3: =MIN(B2:B2500) -> 0
J4: AVE | K4: =AVERAGE(B2:B2500) -> 0

Sheet Sheet34
A1: Depth | B1: x | C1: Actual+ | D1: Actual- | E1: Planned+ | F1: Planned- | G1: Planned diameter | H1: Actual deviation X | J1: Hole Number | M1: =Information!C2 -> 0 | N1: =Information!C3 -> 0
A2: 0 | B2: 0 | C2: =B2/2 -> 0 | D2: =(B2-(B2*2))/2 -> 0 | E2: =G2/2 -> 0 | F2: =(G2-(G2*2))/2 -> 0 | G2: =Information!C$4 -> 0 | H2: =B2-G2 -> 0 | J2: MAX | K2: =MAX(B2:B2500) -> 0
J3: MIN | K3: =MIN(B2:B2500) -> 0
J4: AVE | K4: =AVERAGE(B2:B2500) -> 0

Sheet Sheet35
A1: Depth | B1: x | C1: Actual+ | D1: Actual- | E1: Planned+ | F1: Planned- | G1: Planned diameter | H1: Actual deviation X | J1: Hole Number | M1: =Information!C2 -> 0 | N1: =Information!C3 -> 0
A2: 0 | B2: 0 | C2: =B2/2 -> 0 | D2: =(B2-(B2*2))/2 -> 0 | E2: =G2/2 -> 0 | F2: =(G2-(G2*2))/2 -> 0 | G2: =Information!C$4 -> 0 | H2: =B2-G2 -> 0 | J2: MAX | K2: =MAX(B2:B2500) -> 0
J3: MIN | K3: =MIN(B2:B2500) -> 0
J4: AVE | K4: =AVERAGE(B2:B2500) -> 0

Sheet Sheet36
A1: Depth | B1: x | C1: Actual+ | D1: Actual- | E1: Planned+ | F1: Planned- | G1: Planned diameter | H1: Actual deviation X | J1: Hole Number | M1: =Information!C2 -> 0 | N1: =Information!C3 -> 0
A2: 0 | B2: 0 | C2: =B2/2 -> 0 | D2: =(B2-(B2*2))/2 -> 0 | E2: =G2/2 -> 0 | F2: =(G2-(G2*2))/2 -> 0 | G2: =Information!C$4 -> 0 | H2: =B2-G2 -> 0 | J2: MAX | K2: =MAX(B2:B2500) -> 0
J3: MIN | K3: =MIN(B2:B2500) -> 0
J4: AVE | K4: =AVERAGE(B2:B2500) -> 0

Sheet Sheet37
A1: Depth | B1: x | C1: Actual+ | D1: Actual- | E1: Planned+ | F1: Planned- | G1: Planned diameter | H1: Actual deviation X | J1: Hole Number | M1: =Information!C2 -> 0 | N1: =Information!C3 -> 0
A2: 0 | B2: 0 | C2: =B2/2 -> 0 | D2: =(B2-(B2*2))/2 -> 0 | E2: =G2/2 -> 0 | F2: =(G2-(G2*2))/2 -> 0 | G2: =Information!C$4 -> 0 | H2: =B2-G2 -> 0 | J2: MAX | K2: =MAX(B2:B2500) -> 0
J3: MIN | K3: =MIN(B2:B2500) -> 0
J4: AVE | K4: =AVERAGE(B2:B2500) -> 0

Sheet Sheet38
A1: Depth | B1: x | C1: Actual+ | D1: Actual- | E1: Planned+ | F1: Planned- | G1: Planned diameter | H1: Actual deviation X | J1: Hole Number | M1: =Information!C2 -> 0 | N1: =Information!C3 -> 0
A2: 0 | B2: 0 | C2: =B2/2 -> 0 | D2: =(B2-(B2*2))/2 -> 0 | E2: =G2/2 -> 0 | F2: =(G2-(G2*2))/2 -> 0 | G2: =Information!C$4 -> 0 | H2: =B2-G2 -> 0 | J2: MAX | K2: =MAX(B2:B2500) -> 0
J3: MIN | K3: =MIN(B2:B2500) -> 0
J4: AVE | K4: =AVERAGE(B2:B2500) -> 0

Sheet Sheet39
A1: Depth | B1: x | C1: Actual+ | D1: Actual- | E1: Planned+ | F1: Planned- | G1: Planned diameter | H1: Actual deviation X | J1: Hole Number | M1: =Information!C2 -> 0 | N1: =Information!C3 -> 0
A2: 0 | B2: 0 | C2: =B2/2 -> 0 | D2: =(B2-(B2*2))/2 -> 0 | E2: =G2/2 -> 0 | F2: =(G2-(G2*2))/2 -> 0 | G2: =Information!C$4 -> 0 | H2: =B2-G2 -> 0 | J2: MAX | K2: =MAX(B2:B2500) -> 0
J3: MIN | K3: =MIN(B2:B2500) -> 0
J4: AVE | K4: =AVERAGE(B2:B2500) -> 0

Sheet Sheet40
A1: Depth | B1: x | C1: Actual+ | D1: Actual- | E1: Planned+ | F1: Planned- | G1: Planned diameter | H1: Actual deviation X | J1: Hole Number | M1: =Information!C2 -> 0 | N1: =Information!C3 -> 0
A2: 0 | B2: 0 | C2: =B2/2 -> 0 | D2: =(B2-(B2*2))/2 -> 0 | E2: =G2/2 -> 0 | F2: =(G2-(G2*2))/2 -> 0 | G2: =Information!C$4 -> 0 | H2: =B2-G2 -> 0 | J2: MAX | K2: =MAX(B2:B2500) -> 0
J3: MIN | K3: =MIN(B2:B2500) -> 0
J4: AVE | K4: =AVERAGE(B2:B2500) -> 0

Sheet Sheet41
A1: Depth | B1: x | C1: Actual+ | D1: Actual- | E1: Planned+ | F1: Planned- | G1: Planned diameter | H1: Actual deviation X | J1: Hole Number | M1: =Information!C2 -> 0 | N1: =Information!C3 -> 0
A2: 0 | B2: 0 | C2: =B2/2 -> 0 | D2: =(B2-(B2*2))/2 -> 0 | E2: =G2/2 -> 0 | F2: =(G2-(G2*2))/2 -> 0 | G2: =Information!C$4 -> 0 | H2: =B2-G2 -> 0 | J2: MAX | K2: =MAX(B2:B2500) -> 0
J3: MIN | K3: =MIN(B2:B2500) -> 0
J4: AVE | K4: =AVERAGE(B2:B2500) -> 0

Sheet Sheet42
A1: Depth | B1: x | C1: Actual+ | D1: Actual- | E1: Planned+ | F1: Planned- | G1: Planned diameter | H1: Actual deviation X | J1: Hole Number | M1: =Information!C2 -> 0 | N1: =Information!C3 -> 0
A2: 0 | B2: 0 | C2: =B2/2 -> 0 | D2: =(B2-(B2*2))/2 -> 0 | E2: =G2/2 -> 0 | F2: =(G2-(G2*2))/2 -> 0 | G2: =Information!C$4 -> 0 | H2: =B2-G2 -> 0 | J2: MAX | K2: =MAX(B2:B2500) -> 0
J3: MIN | K3: =MIN(B2:B2500) -> 0
J4: AVE | K4: =AVERAGE(B2:B2500) -> 0

Sheet Sheet43
A1: Depth | B1: x | C1: Actual+ | D1: Actual- | E1: Planned+ | F1: Planned- | G1: Planned diameter | H1: Actual deviation X | J1: Hole Number | M1: =Information!C2 -> 0 | N1: =Information!C3 -> 0
A2: 0 | B2: 0 | C2: =B2/2 -> 0 | D2: =(B2-(B2*2))/2 -> 0 | E2: =G2/2 -> 0 | F2: =(G2-(G2*2))/2 -> 0 | G2: =Information!C$4 -> 0 | H2: =B2-G2 -> 0 | J2: MAX | K2: =MAX(B2:B2500) -> 0
J3: MIN | K3: =MIN(B2:B2500) -> 0
J4: AVE | K4: =AVERAGE(B2:B2500) -> 0

Sheet Sheet44
A1: Depth | B1: x | C1: Actual+ | D1: Actual- | E1: Planned+ | F1: Planned- | G1: Planned diameter | H1: Actual deviation X | J1: Hole Number | M1: =Information!C2 -> 0 | N1: =Information!C3 -> 0
A2: 0 | B2: 0 | C2: =B2/2 -> 0 | D2: =(B2-(B2*2))/2 -> 0 | E2: =G2/2 -> 0 | F2: =(G2-(G2*2))/2 -> 0 | G2: =Information!C$4 -> 0 | H2: =B2-G2 -> 0 | J2: MAX | K2: =MAX(B2:B2500) -> 0
J3: MIN | K3: =MIN(B2:B2500) -> 0
J4: AVE | K4: =AVERAGE(B2:B2500) -> 0

Sheet Sheet45
A1: Depth | B1: x | C1: Actual+ | D1: Actual- | E1: Planned+ | F1: Planned- | G1: Planned diameter | H1: Actual deviation X | J1: Hole Number | M1: =Information!C2 -> 0 | N1: =Information!C3 -> 0
A2: 0 | B2: 0 | C2: =B2/2 -> 0 | D2: =(B2-(B2*2))/2 -> 0 | E2: =G2/2 -> 0 | F2: =(G2-(G2*2))/2 -> 0 | G2: =Information!C$4 -> 0 | H2: =B2-G2 -> 0 | J2: MAX | K2: =MAX(B2:B2500) -> 0
J3: MIN | K3: =MIN(B2:B2500) -> 0
J4: AVE | K4: =AVERAGE(B2:B2500) -> 0

Sheet Sheet46
A1: Depth | B1: x | C1: Actual+ | D1: Actual- | E1: Planned+ | F1: Planned- | G1: Planned diameter | H1: Actual deviation X | J1: Hole Number | M1: =Information!C2 -> 0 | N1: =Information!C3 -> 0
A2: 0 | B2: 0 | C2: =B2/2 -> 0 | D2: =(B2-(B2*2))/2 -> 0 | E2: =G2/2 -> 0 | F2: =(G2-(G2*2))/2 -> 0 | G2: =Information!C$4 -> 0 | H2: =B2-G2 -> 0 | J2: MAX | K2: =MAX(B2:B2500) -> 0
J3: MIN | K3: =MIN(B2:B2500) -> 0
J4: AVE | K4: =AVERAGE(B2:B2500) -> 0

Sheet Sheet47
A1: Depth | B1: x | C1: Actual+ | D1: Actual- | E1: Planned+ | F1: Planned- | G1: Planned diameter | H1: Actual deviation X | J1: Hole Number | M1: =Information!C2 -> 0 | N1: =Information!C3 -> 0
A2: 0 | B2: 0 | C2: =B2/2 -> 0 | D2: =(B2-(B2*2))/2 -> 0 | E2: =G2/2 -> 0 | F2: =(G2-(G2*2))/2 -> 0 | G2: =Information!C$4 -> 0 | H2: =B2-G2 -> 0 | J2: MAX | K2: =MAX(B2:B2500) -> 0
J3: MIN | K3: =MIN(B2:B2500) -> 0
J4: AVE | K4: =AVERAGE(B2:B2500) -> 0

Sheet Sheet48
A1: Depth | B1: x | C1: Actual+ | D1: Actual- | E1: Planned+ | F1: Planned- | G1: Planned diameter | H1: Actual deviation X | J1: Hole Number | M1: =Information!C2 -> 0 | N1: =Information!C3 -> 0
A2: 0 | B2: 0 | C2: =B2/2 -> 0 | D2: =(B2-(B2*2))/2 -> 0 | E2: =G2/2 -> 0 | F2: =(G2-(G2*2))/2 -> 0 | G2: =Information!C$4 -> 0 | H2: =B2-G2 -> 0 | J2: MAX | K2: =MAX(B2:B2500) -> 0
J3: MIN | K3: =MIN(B2:B2500) -> 0
J4: AVE | K4: =AVERAGE(B2:B2500) -> 0

Sheet Sheet49
A1: Depth | B1: x | C1: Actual+ | D1: Actual- | E1: Planned+ | F1: Planned- | G1: Planned diameter | H1: Actual deviation X | J1: Hole Number | M1: =Information!C2 -> 0 | N1: =Information!C3 -> 0
A2: 0 | B2: 0 | C2: =B2/2 -> 0 | D2: =(B2-(B2*2))/2 -> 0 | E2: =G2/2 -> 0 | F2: =(G2-(G2*2))/2 -> 0 | G2: =Information!C$4 -> 0 | H2: =B2-G2 -> 0 | J2: MAX | K2: =MAX(B2:B2500) -> 0
J3: MIN | K3: =MIN(B2:B2500) -> 0
J4: AVE | K4: =AVERAGE(B2:B2500) -> 0

Sheet Sheet50
A1: Depth | B1: x | C1: Actual+ | D1: Actual- | E1: Planned+ | F1: Planned- | G1: Planned diameter | H1: Actual deviation X | J1: Hole Number | M1: =Information!C2 -> 0 | N1: =Information!C3 -> 0
A2: 0 | B2: 0 | C2: =B2/2 -> 0 | D2: =(B2-(B2*2))/2 -> 0 | E2: =G2/2 -> 0 | F2: =(G2-(G2*2))/2 -> 0 | G2: =Information!C$4 -> 0 | H2: =B2-G2 -> 0 | J2: MAX | K2: =MAX(B2:B2500) -> 0
J3: MIN | K3: =MIN(B2:B2500) -> 0
J4: AVE | K4: =AVERAGE(B2:B2500) -> 0
